Workbook

Sheet 1. Phân bổ Ngân sách
A1: MÔ HÌNH PHÂN BỔ NGÂN SÁCH HOẠT ĐỘNG - NGUỒN VỐN NGHIÊNG COMPLEX
A3: 1. GIẢ ĐỊNH CHUNG (INPUT CÓ THỂ THAY ĐỔI) | J3: 3. CƠ CHẾ PHÂN BỔ QUỸ LEADER TEAM
A4: Doanh thu Hợp đồng giả định (Doanh số hệ thống): | C4: 5000000000
A5: Tỷ lệ Ngân sách Hoạt động thực tế: | C5: 0.15 | J5: Quỹ Leader Team khả dụng: | M5: =F19 -> 159500000
A6: Tổng Ngân sách Hoạt động: | C6: =C4*C5 -> 750000000 | J6: Phần Chia đều (30%): | M6: =M5*0.3 -> 47850000
J7: Phần Hiệu quả (70%): | M7: =M5*0.7 -> 111650000
A8: 2. ĐỊNH MỨC PHÂN BỔ CHI TIẾT CÁC QUỸ VÀ BỘ PHẬN
A9: Tên Quỹ / Khấu Phần bổ | B9: Tỷ lệ phân bổ (%) | C9: Tỷ lệ trên Doanh thu (%) | D9: Số tiền phân bổ (VND) | E9: Trích nạp thêm từ HĐ (VND) | F9: Tổng ngân sách sau cộng (VND) | G9: Đã thực chi thực tế (VND) | H9: Số dư Khả dụng còn lại (VND) | J9: BẢNG PHÂN PHỐI QUỸ THEO CHỨC DANH
A10: Sale trực tiếp - Pro sale (Nguồn khách) | B10: =C10/C$5 -> 0.4 | C10: 0.06 | D10: =C10*$C$4 -> 300000000 | E10: ='5. Nhật ký Hợp đồng'!S5 -> 30000000 | F10: =D10+E10 -> 330000000 | G10: ='5. Nhật ký Hợp đồng'!T5 -> 30000000 | H10: =F10-G10 -> 300000000 | J10: Chức danh | K10: Tỷ lệ % | L10: Số lượng | M10: Thực nhận / người | N10: Điều kiện duy trì tháng cấp
A11: Tri ân kết nối sale trực tiếp | B11: =C11/C$5 -> 0.066666667 | C11: 0.01 | D11: =C11*$C$4 -> 50000000 | E11: ='5. Nhật ký Hợp đồng'!S6 -> 5000000 | F11: =D11+E11 -> 55000000 | G11: ='5. Nhật ký Hợp đồng'!T6 -> 5000000 | H11: =F11-G11 -> 50000000 | J11: Giám đốc | K11: 0.5 | L11: 5 | M11: =($M$7*K11)/L11 -> 11165000 | N11: Tối thiểu 1 PGD & duy trì 20 thành viên trong team
A12: Tri ân hỗ trợ sale | B12: =C12/C$5 -> 0.033333333 | C12: 0.005 | D12: =C12*$C$4 -> 25000000 | E12: ='5. Nhật ký Hợp đồng'!S7 -> 2500000 | F12: =D12+E12 -> 27500000 | G12: ='5. Nhật ký Hợp đồng'!T7 -> 2500000 | H12: =F12-G12 -> 25000000 | J12: Phó Giám đốc | K12: 0.3 | L12: 4 | M12: =($M$7*K12)/L12 -> 8373750 | N12: Tối thiểu 1 Trưởng phòng & duy trì 10 thành viên
A13: Quỹ Sự kiện & Chốt hợp đồng | B13: =C13/C$5 -> 0.033333333 | C13: 0.005 | D13: =C13*$C$4 -> 25000000 | E13: ='5. Nhật ký Hợp đồng'!S8 -> 2500000 | F13: =D13+E13 -> 27500000 | G13: ='5. Nhật ký Hợp đồng'!T8 -> 3000000 | H13: =F13-G13 -> 24500000 | J13: Trưởng phòng | K13: 0.2 | L13: 6 | M13: =($M$7*K13)/L13 -> 3721666.7 | N13: Duy trì tối thiểu 5 thành viên trong nhóm
A14: Quỹ Chăm sóc khách hàng | B14: =C14/C$5 -> 0.013333333 | C14: 0.002 | D14: =C14*$C$4 -> 10000000 | E14: ='5. Nhật ký Hợp đồng'!S9 -> 1000000 | F14: =D14+E14 -> 11000000 | G14: ='5. Nhật ký Hợp đồng'!T9 -> 3000000 | H14: =F14-G14 -> 8000000
A15: Quỹ Đào tạo Chuyên môn & Kỹ năng | B15: =C15/C$5 -> 0.02 | C15: 0.003 | D15: =C15*$C$4 -> 15000000 | E15: ='5. Nhật ký Hợp đồng'!S10 -> 1500000 | F15: =D15+E15 -> 16500000 | G15: ='5. Nhật ký Hợp đồng'!T10 -> 16000000 | H15: =F15-G15 -> 500000 | J15: ĐIỀU KIỆN DUY TRÌ VÀ THAM GIA ĂN CHIA QUỸ LEADER TEAM
A16: Quỹ Thi đua & Chương trình thúc đẩy | B16: =C16/C$5 -> 0.053333333 | C16: 0.008 | D16: =C16*$C$4 -> 40000000 | E16: ='5. Nhật ký Hợp đồng'!S11 -> 4000000 | F16: =D16+E16 -> 44000000 | G16: ='5. Nhật ký Hợp đồng'!T11 -> 10000000 | H16: =F16-G16 -> 34000000 | J16: - Tuyển dụng tối thiểu 3 tháng / ProSale hoạt động thực tế
A17: Chi phí Công tác phí | B17: =C17/C$5 -> 0.02 | C17: 0.003 | D17: =C17*$C$4 -> 15000000 | E17: ='5. Nhật ký Hợp đồng'!S12 -> 1500000 | F17: =D17+E17 -> 16500000 | G17: ='5. Nhật ký Hợp đồng'!T12 -> 1500000 | H17: =F17-G17 -> 15000000 | J17: - Không nghỉ họp liên tiếp 2 buổi / tháng (Dù có đủ doanh số)
A18: Quỹ Vận hành & Bộ phận hỗ trợ | B18: =C18/C$5 -> 0.36 | C18: =sum(C19:C23) -> 0.054 | D18: =C18*$C$4 -> 270000000 | E18: ='5. Nhật ký Hợp đồng'!S14 -> 12500000 | F18: =D18+E18 -> 282500000 | G18: ='5. Nhật ký Hợp đồng'!T14 -> 0 | H18: =F18-G18 -> 282500000 | J18: - Leader tự phát sinh hợp đồng cá nhân trong vòng 3 tháng
A19: Leader team - giám đốc Kd | B19: =C19/C$5 -> 0.19333333 | C19: 0.029 | D19: =C19*$C$4 -> 145000000 | E19: ='5. Nhật ký Hợp đồng'!S13 -> 14500000 | F19: =D19+E19 -> 159500000 | G19: ='5. Nhật ký Hợp đồng'!T13 -> 0 | H19: =F19-G19 -> 159500000 | J19: - Duy trì tối thiểu 5 ProSale hoạt động trong nhóm
A20: Tri ân kết nối phó tổng | B20: =C20/C$5 -> 0.033333333 | C20: 0.005
A21: Tổng điềù hành | B21: =C21/C$5 -> 0.033333333 | C21: 0.005
A22: Phó tổng | B22: =C22/C$5 -> 0.08 | C22: 0.012
A23: Quỹ hỗ trợ & dự phòng | B23: =C23/C$5 -> 0.02 | C23: 0.003
A24: TỔNG CỘNG NGÂN SÁCH | B24: =SUM(B10:B18) -> 1 | C24: =SUM(C10:C18) -> 0.15 | D24: =SUM(D10:D23) -> 895000000 | E24: =SUM(E10:E23) -> 75000000 | F24: =SUM(F10:F23) -> 970000000 | G24: =SUM(G10:G23) -> 71000000 | H24: =SUM(H10:H23) -> 899000000 | J24: - Team phát sinh ít nhất 1 hợp đồng / tháng để đảm bảo duy trì nhóm
A26: 3. THAM CHIẾU QUY ĐỔI TOKEN ĐÀO TẠO (QUỸ ĐÀO TẠO ĐỒNG)
A27: Hạng đào tạo | B27: Số lượng Token quy đổi | C27: Giá trị quy định (Nếu cố định tham chiếu)
A28: Hạng A (Chuyên nghiệp / Giảng viên) | B28: 10 | C28: Tính động theo bể ngân sách từng buổi học (Tab 7)
A29: Hạng B (Trợ giảng có kinh nghiệm) | B29: 5 | C29: Tính động theo bể ngân sách từng buổi học (Tab 7)
A30: Hạng C (Học viên xuất sắc / Hộ) | B30: 3 | C30: Tính động theo bể ngân sách từng buổi học (Tab 7)
A31: Hạng D (Học viên tham gia đầy đủ) | B31: 1 | C31: Tính động theo bể ngân sách từng buổi học (Tab 7)

Sheet 2. Danh sách Thành viên
A1: DANH SÁCH THÀNH VIÊN VÀ KIỂM TRA ĐIỀU KIỆN CHỨC DANH CHI TIẾT (ẢNH I) | U1: Từ ngày: | V1: 46235
U2: Đến ngày: | V2: 46265
A3: Mã TV (SĐT) | B3: Họ và Tên | C3: Số điện thoại | D3: Căn cước (CCCD) | E3: Số TK | F3: Ngân hàng | G3: Email | H3: Người giới thiệu (Mã TV) | I3: Họ tên Người giới thiệu | J3: Chức danh Đăng ký | K3: Nhóm/Team | L3: Sĩ số Nhóm (COUNTIF) | M3: Số Thành viên (Nhóm) | N3: Số Trưởng phòng (Nhóm) | O3: Số Phó GD (Nhóm) | P3: Chức danh | Q3: Số buổi vắng (Liên tiếp) | R3: HĐ cá nhân (3 tháng qua) | S3: HĐ nhóm (Tháng này) | T3: Số lần làm Khách | U3: Số lần đi mời | V3: Số lượng khách mời tham gia | W3: Tiền Tiệc trà tự đóng (VND) | X3: Tổng Thù lao Sự kiện (VND) | Y3: Tổng Thù lao Hợp đồng (VND) | Z3: Tổng Thù lao Đào tạo (VND) | AA3: Thực nhận Cuối kỳ (VND)
A4: 0912345671 | B4: Nguyễn Văn Hoàng | C4: 0912345671 | D4: 001096001234 | E4: 1903456789 | F4: Techcombank | G4: hoang.nv@vov.vn | H4: Công ty | I4: Công ty | J4: Giám đốc | K4: Lửa Xanh | L4: =COUNTIF($K$4:$K$40, K4) -> 8 | M4: =COUNTIFS($K$4:$K$40, K4, $J$4:$J$40, "Thành viên") -> 5 | N4: =COUNTIFS($K$4:$K$40, K4, $J$4:$J$40, "Trưởng phòng") -> 1 | O4: =COUNTIFS($K$4:$K$40, K4, $J$4:$J$40, "Phó Giám đốc") -> 1 | P4: =IF(J4="Giám đốc", IF(AND(L4>=20, O4>=1), "Giám đốc", "Thành viên"), IF(J4="Phó Giám đốc", IF(AND(L4>=10, N4>=1), "Phó Giám đốc", "Thành viên"), IF(J4="Trưởng phòng", IF(L4>=5, "Trưởng phòng", "Thành viên"), "Thành viên"))) -> Thành viên | Q4: 0 | R4: Có | S4: Có | T4: =COUNTIFS('4. Chi tiết Sự kiện'!$C$4:$C$103, A4, '4. Chi tiết Sự kiện'!$E$4:$E$103, "Khách mời", '4. Chi tiết Sự kiện'!$H$4:$H$103, "Có", '4. Chi tiết Sự kiện'!$B$4:$B$103, ">="&$V$1, '4. Chi tiết Sự kiện'!$B$4:$B$103, "<="&$V$2) -> 0 | U4: =COUNTIFS('4. Chi tiết Sự kiện'!$F$4:$F$103, A4, '4. Chi tiết Sự kiện'!$B$4:$B$103, ">="&$V$1, '4. Chi tiết Sự kiện'!$B$4:$B$103, "<="&$V$2) -> 4 | V4: =COUNTIFS('4. Chi tiết Sự kiện'!$F$4:$F$103, A4, '4. Chi tiết Sự kiện'!$E$4:$E$103, "Khách mời", '4. Chi tiết Sự kiện'!$B$4:$B$103, ">="&$V$1, '4. Chi tiết Sự kiện'!$B$4:$B$103, "<="&$V$2) -> 4 | W4: =SUMIFS('4. Chi tiết Sự kiện'!$L$4:$L$103, '4. Chi tiết Sự kiện'!$C$4:$C$103, A4, '4. Chi tiết Sự kiện'!$B$4:$B$103, ">="&$V$1, '4. Chi tiết Sự kiện'!$B$4:$B$103, "<="&$V$2) -> 0 | X4: =SUMIFS('4. Chi tiết Sự kiện'!$M$4:$M$103, '4. Chi tiết Sự kiện'!$C$4:$C$103, A4, '4. Chi tiết Sự kiện'!$B$4:$B$103, ">="&$V$1, '4. Chi tiết Sự kiện'!$B$4:$B$103, "<="&$V$2) -> 500000 | Y4: =SUMIFS('5. Nhật ký Hợp đồng'!$K$4:$K$103, '5. Nhật ký Hợp đồng'!$E$4:$E$103, A4, '5. Nhật ký Hợp đồng'!$N$4:$N$103, "Đã duyệt", '5. Nhật ký Hợp đồng'!$B$4:$B$103, ">="&$V$1, '5. Nhật ký Hợp đồng'!$B$4:$B$103, "<="&$V$2) + SUMIFS('5. Nhật ký Hợp đồng'!$L$4:$L$103, '5. Nhật ký Hợp đồng'!$G$4:$G$103, A4, '5. Nhật ký Hợp đồng'!$N$4:$N$103, "Đã duyệt", '5. Nhật ký Hợp đồng'!$B$4:$B$103, ">="&$V$1, '5. Nhật ký Hợp đồng'!$B$4:$B$103, "<="&$V$2) + SUMIFS('5. Nhật ký Hợp đồng'!$M$4:$M$103, '5. Nhật ký Hợp đồng'!$I$4:$I$103, A4, '5. Nhật ký Hợp đồng'!$N$4:$N$103, "Đã duyệt", '5. Nhật ký Hợp đồng'!$B$4:$B$103, ">="&$V$1, '5. Nhật ký Hợp đồng'!$B$4:$B$103, "<="&$V$2) -> 13000000 | Z4: =SUMIFS('7. Nhật ký Đào tạo'!$L$4:$L$103, '7. Nhật ký Đào tạo'!$B$4:$B$103, A4, '7. Nhật ký Đào tạo'!$K$4:$K$103, "Đã duyệt", '7. Nhật ký Đào tạo'!$M$4:$M$103, ">="&$V$1, '7. Nhật ký Đào tạo'!$M$4:$M$103, "<="&$V$2) -> 7543859.6 | AA4: =X4+Y4+Z4-W4 -> 21043860
A5: 0912345672 | B5: Lê Minh Anh | C5: 0912345672 | D5: 001096005678 | E5: 00710009999 | F5: Vietcombank | G5: anh.lm@vov.vn | H5: 0912345671 | I5: Nguyễn Văn Hoàng | J5: Phó Giám đốc | K5: Lửa Xanh | L5: =COUNTIF($K$4:$K$40, K5) -> 8 | M5: =COUNTIFS($K$4:$K$40, K5, $J$4:$J$40, "Thành viên") -> 5 | N5: =COUNTIFS($K$4:$K$40, K5, $J$4:$J$40, "Trưởng phòng") -> 1 | O5: =COUNTIFS($K$4:$K$40, K5, $J$4:$J$40, "Phó Giám đốc") -> 1 | P5: =IF(J5="Giám đốc", IF(AND(L5>=20, O5>=1), "Giám đốc", "Thành viên"), IF(J5="Phó Giám đốc", IF(AND(L5>=10, N5>=1), "Phó Giám đốc", "Thành viên"), IF(J5="Trưởng phòng", IF(L5>=5, "Trưởng phòng", "Thành viên"), "Thành viên"))) -> Thành viên | Q5: 0 | R5: Có | S5: Có | T5: =COUNTIFS('4. Chi tiết Sự kiện'!$C$4:$C$103, A5, '4. Chi tiết Sự kiện'!$E$4:$E$103, "Khách mời", '4. Chi tiết Sự kiện'!$H$4:$H$103, "Có", '4. Chi tiết Sự kiện'!$B$4:$B$103, ">="&$V$1, '4. Chi tiết Sự kiện'!$B$4:$B$103, "<="&$V$2) -> 0 | U5: =COUNTIFS('4. Chi tiết Sự kiện'!$F$4:$F$103, A5, '4. Chi tiết Sự kiện'!$B$4:$B$103, ">="&$V$1, '4. Chi tiết Sự kiện'!$B$4:$B$103, "<="&$V$2) -> 5 | V5: =COUNTIFS('4. Chi tiết Sự kiện'!$F$4:$F$103, A5, '4. Chi tiết Sự kiện'!$E$4:$E$103, "Khách mời", '4. Chi tiết Sự kiện'!$B$4:$B$103, ">="&$V$1, '4. Chi tiết Sự kiện'!$B$4:$B$103, "<="&$V$2) -> 4 | W5: =SUMIFS('4. Chi tiết Sự kiện'!$L$4:$L$103, '4. Chi tiết Sự kiện'!$C$4:$C$103, A5, '4. Chi tiết Sự kiện'!$B$4:$B$103, ">="&$V$1, '4. Chi tiết Sự kiện'!$B$4:$B$103, "<="&$V$2) -> 0 | X5: =SUMIFS('4. Chi tiết Sự kiện'!$M$4:$M$103, '4. Chi tiết Sự kiện'!$C$4:$C$103, A5, '4. Chi tiết Sự kiện'!$B$4:$B$103, ">="&$V$1, '4. Chi tiết Sự kiện'!$B$4:$B$103, "<="&$V$2) -> 700000 | Y5: =SUMIFS('5. Nhật ký Hợp đồng'!$K$4:$K$103, '5. Nhật ký Hợp đồng'!$E$4:$E$103, A5, '5. Nhật ký Hợp đồng'!$N$4:$N$103, "Đã duyệt", '5. Nhật ký Hợp đồng'!$B$4:$B$103, ">="&$V$1, '5. Nhật ký Hợp đồng'!$B$4:$B$103, "<="&$V$2) + SUMIFS('5. Nhật ký Hợp đồng'!$L$4:$L$103, '5. Nhật ký Hợp đồng'!$G$4:$G$103, A5, '5. Nhật ký Hợp đồng'!$N$4:$N$103, "Đã duyệt", '5. Nhật ký Hợp đồng'!$B$4:$B$103, ">="&$V$1, '5. Nhật ký Hợp đồng'!$B$4:$B$103, "<="&$V$2) + SUMIFS('5. Nhật ký Hợp đồng'!$M$4:$M$103, '5. Nhật ký Hợp đồng'!$I$4:$I$103, A5, '5. Nhật ký Hợp đồng'!$N$4:$N$103, "Đã duyệt", '5. Nhật ký Hợp đồng'!$B$4:$B$103, ">="&$V$1, '5. Nhật ký Hợp đồng'!$B$4:$B$103, "<="&$V$2) -> 10000000 | Z5: =SUMIFS('7. Nhật ký Đào tạo'!$L$4:$L$103, '7. Nhật ký Đào tạo'!$B$4:$B$103, A5, '7. Nhật ký Đào tạo'!$K$4:$K$103, "Đã duyệt", '7. Nhật ký Đào tạo'!$M$4:$M$103, ">="&$V$1, '7. Nhật ký Đào tạo'!$M$4:$M$103, "<="&$V$2) -> 3611111.1 | AA5: =X5+Y5+Z5-W5 -> 14311111
A6: 0912345673 | B6: Trần Thị Vân | C6: 0912345673 | D6: 001096009999 | E6: 1023456789 | F6: Vietinbank | G6: van.tt@vov.vn | H6: 0912345672 | I6: Lê Minh Anh | J6: Trưởng phòng | K6: Lửa Xanh | L6: =COUNTIF($K$4:$K$40, K6) -> 8 | M6: =COUNTIFS($K$4:$K$40, K6, $J$4:$J$40, "Thành viên") -> 5 | N6: =COUNTIFS($K$4:$K$40, K6, $J$4:$J$40, "Trưởng phòng") -> 1 | O6: =COUNTIFS($K$4:$K$40, K6, $J$4:$J$40, "Phó Giám đốc") -> 1 | P6: =IF(J6="Giám đốc", IF(AND(L6>=20, O6>=1), "Giám đốc", "Thành viên"), IF(J6="Phó Giám đốc", IF(AND(L6>=10, N6>=1), "Phó Giám đốc", "Thành viên"), IF(J6="Trưởng phòng", IF(L6>=5, "Trưởng phòng", "Thành viên"), "Thành viên"))) -> Trưởng phòng | Q6: 0 | R6: Có | S6: Có | T6: =COUNTIFS('4. Chi tiết Sự kiện'!$C$4:$C$103, A6, '4. Chi tiết Sự kiện'!$E$4:$E$103, "Khách mời", '4. Chi tiết Sự kiện'!$H$4:$H$103, "Có", '4. Chi tiết Sự kiện'!$B$4:$B$103, ">="&$V$1, '4. Chi tiết Sự kiện'!$B$4:$B$103, "<="&$V$2) -> 0 | U6: =COUNTIFS('4. Chi tiết Sự kiện'!$F$4:$F$103, A6, '4. Chi tiết Sự kiện'!$B$4:$B$103, ">="&$V$1, '4. Chi tiết Sự kiện'!$B$4:$B$103, "<="&$V$2) -> 0 | V6: =COUNTIFS('4. Chi tiết Sự kiện'!$F$4:$F$103, A6, '4. Chi tiết Sự kiện'!$E$4:$E$103, "Khách mời", '4. Chi tiết Sự kiện'!$B$4:$B$103, ">="&$V$1, '4. Chi tiết Sự kiện'!$B$4:$B$103, "<="&$V$2) -> 0 | W6: =SUMIFS('4. Chi tiết Sự kiện'!$L$4:$L$103, '4. Chi tiết Sự kiện'!$C$4:$C$103, A6, '4. Chi tiết Sự kiện'!$B$4:$B$103, ">="&$V$1, '4. Chi tiết Sự kiện'!$B$4:$B$103, "<="&$V$2) -> 0 | X6: =SUMIFS('4. Chi tiết Sự kiện'!$M$4:$M$103, '4. Chi tiết Sự kiện'!$C$4:$C$103, A6, '4. Chi tiết Sự kiện'!$B$4:$B$103, ">="&$V$1, '4. Chi tiết Sự kiện'!$B$4:$B$103, "<="&$V$2) -> 600000 | Y6: =SUMIFS('5. Nhật ký Hợp đồng'!$K$4:$K$103, '5. Nhật ký Hợp đồng'!$E$4:$E$103, A6, '5. Nhật ký Hợp đồng'!$N$4:$N$103, "Đã duyệt", '5. Nhật ký Hợp đồng'!$B$4:$B$103, ">="&$V$1, '5. Nhật ký Hợp đồng'!$B$4:$B$103, "<="&$V$2) + SUMIFS('5. Nhật ký Hợp đồng'!$L$4:$L$103, '5. Nhật ký Hợp đồng'!$G$4:$G$103, A6, '5. Nhật ký Hợp đồng'!$N$4:$N$103, "Đã duyệt", '5. Nhật ký Hợp đồng'!$B$4:$B$103, ">="&$V$1, '5. Nhật ký Hợp đồng'!$B$4:$B$103, "<="&$V$2) + SUMIFS('5. Nhật ký Hợp đồng'!$M$4:$M$103, '5. Nhật ký Hợp đồng'!$I$4:$I$103, A6, '5. Nhật ký Hợp đồng'!$N$4:$N$103, "Đã duyệt", '5. Nhật ký Hợp đồng'!$B$4:$B$103, ">="&$V$1, '5. Nhật ký Hợp đồng'!$B$4:$B$103, "<="&$V$2) -> 1750000 | Z6: =SUMIFS('7. Nhật ký Đào tạo'!$L$4:$L$103, '7. Nhật ký Đào tạo'!$B$4:$B$103, A6, '7. Nhật ký Đào tạo'!$K$4:$K$103, "Đã duyệt", '7. Nhật ký Đào tạo'!$M$4:$M$103, ">="&$V$1, '7. Nhật ký Đào tạo'!$M$4:$M$103, "<="&$V$2) -> 921052.63 | AA6: =X6+Y6+Z6-W6 -> 3271052.6
A7: 0912345674 | B7: Bùi Minh Đức | C7: 0912345674 | D7: 001096001111 | E7: 11112222333 | F7: MB Bank | G7: duc.bm@vov.vn | H7: 0912345672 | I7: Lê Minh Anh | J7: Thành viên | K7: Lửa Xanh | L7: =COUNTIF($K$4:$K$40, K7) -> 8 | M7: =COUNTIFS($K$4:$K$40, K7, $J$4:$J$40, "Thành viên") -> 5 | N7: =COUNTIFS($K$4:$K$40, K7, $J$4:$J$40, "Trưởng phòng") -> 1 | O7: =COUNTIFS($K$4:$K$40, K7, $J$4:$J$40, "Phó Giám đốc") -> 1 | P7: =IF(J7="Giám đốc", IF(AND(L7>=20, O7>=1), "Giám đốc", "Thành viên"), IF(J7="Phó Giám đốc", IF(AND(L7>=10, N7>=1), "Phó Giám đốc", "Thành viên"), IF(J7="Trưởng phòng", IF(L7>=5, "Trưởng phòng", "Thành viên"), "Thành viên"))) -> Thành viên | Q7: 1 | R7: Có | S7: Có | T7: =COUNTIFS('4. Chi tiết Sự kiện'!$C$4:$C$103, A7, '4. Chi tiết Sự kiện'!$E$4:$E$103, "Khách mời", '4. Chi tiết Sự kiện'!$H$4:$H$103, "Có", '4. Chi tiết Sự kiện'!$B$4:$B$103, ">="&$V$1, '4. Chi tiết Sự kiện'!$B$4:$B$103, "<="&$V$2) -> 0 | U7: =COUNTIFS('4. Chi tiết Sự kiện'!$F$4:$F$103, A7, '4. Chi tiết Sự kiện'!$B$4:$B$103, ">="&$V$1, '4. Chi tiết Sự kiện'!$B$4:$B$103, "<="&$V$2) -> 0 | V7: =COUNTIFS('4. Chi tiết Sự kiện'!$F$4:$F$103, A7, '4. Chi tiết Sự kiện'!$E$4:$E$103, "Khách mời", '4. Chi tiết Sự kiện'!$B$4:$B$103, ">="&$V$1, '4. Chi tiết Sự kiện'!$B$4:$B$103, "<="&$V$2) -> 0 | W7: =SUMIFS('4. Chi tiết Sự kiện'!$L$4:$L$103, '4. Chi tiết Sự kiện'!$C$4:$C$103, A7, '4. Chi tiết Sự kiện'!$B$4:$B$103, ">="&$V$1, '4. Chi tiết Sự kiện'!$B$4:$B$103, "<="&$V$2) -> 0 | X7: =SUMIFS('4. Chi tiết Sự kiện'!$M$4:$M$103, '4. Chi tiết Sự kiện'!$C$4:$C$103, A7, '4. Chi tiết Sự kiện'!$B$4:$B$103, ">="&$V$1, '4. Chi tiết Sự kiện'!$B$4:$B$103, "<="&$V$2) -> 450000 | Y7: =SUMIFS('5. Nhật ký Hợp đồng'!$K$4:$K$103, '5. Nhật ký Hợp đồng'!$E$4:$E$103, A7, '5. Nhật ký Hợp đồng'!$N$4:$N$103, "Đã duyệt", '5. Nhật ký Hợp đồng'!$B$4:$B$103, ">="&$V$1, '5. Nhật ký Hợp đồng'!$B$4:$B$103, "<="&$V$2) + SUMIFS('5. Nhật ký Hợp đồng'!$L$4:$L$103, '5. Nhật ký Hợp đồng'!$G$4:$G$103, A7, '5. Nhật ký Hợp đồng'!$N$4:$N$103, "Đã duyệt", '5. Nhật ký Hợp đồng'!$B$4:$B$103, ">="&$V$1, '5. Nhật ký Hợp đồng'!$B$4:$B$103, "<="&$V$2) + SUMIFS('5. Nhật ký Hợp đồng'!$M$4:$M$103, '5. Nhật ký Hợp đồng'!$I$4:$I$103, A7, '5. Nhật ký Hợp đồng'!$N$4:$N$103, "Đã duyệt", '5. Nhật ký Hợp đồng'!$B$4:$B$103, ">="&$V$1, '5. Nhật ký Hợp đồng'!$B$4:$B$103, "<="&$V$2) -> 750000 | Z7: =SUMIFS('7. Nhật ký Đào tạo'!$L$4:$L$103, '7. Nhật ký Đào tạo'!$B$4:$B$103, A7, '7. Nhật ký Đào tạo'!$K$4:$K$103, "Đã duyệt", '7. Nhật ký Đào tạo'!$M$4:$M$103, ">="&$V$1, '7. Nhật ký Đào tạo'!$M$4:$M$103, "<="&$V$2) -> 2105263.2 | AA7: =X7+Y7+Z7-W7 -> 3305263.2
A8: 0912345675 | B8: Ngô Thanh Hải | C8: 0912345675 | D8: 001096002222 | E8: 19034444555 | F8: Techcombank | G8: hai.nt@vov.vn | H8: 0912345673 | I8: Trần Thị Vân | J8: Thành viên | K8: Lửa Xanh | L8: =COUNTIF($K$4:$K$40, K8) -> 8 | M8: =COUNTIFS($K$4:$K$40, K8, $J$4:$J$40, "Thành viên") -> 5 | N8: =COUNTIFS($K$4:$K$40, K8, $J$4:$J$40, "Trưởng phòng") -> 1 | O8: =COUNTIFS($K$4:$K$40, K8, $J$4:$J$40, "Phó Giám đốc") -> 1 | P8: =IF(J8="Giám đốc", IF(AND(L8>=20, O8>=1), "Giám đốc", "Thành viên"), IF(J8="Phó Giám đốc", IF(AND(L8>=10, N8>=1), "Phó Giám đốc", "Thành viên"), IF(J8="Trưởng phòng", IF(L8>=5, "Trưởng phòng", "Thành viên"), "Thành viên"))) -> Thành viên | Q8: 0 | R8: Có | S8: Có | T8: =COUNTIFS('4. Chi tiết Sự kiện'!$C$4:$C$103, A8, '4. Chi tiết Sự kiện'!$E$4:$E$103, "Khách mời", '4. Chi tiết Sự kiện'!$H$4:$H$103, "Có", '4. Chi tiết Sự kiện'!$B$4:$B$103, ">="&$V$1, '4. Chi tiết Sự kiện'!$B$4:$B$103, "<="&$V$2) -> 0 | U8: =COUNTIFS('4. Chi tiết Sự kiện'!$F$4:$F$103, A8, '4. Chi tiết Sự kiện'!$B$4:$B$103, ">="&$V$1, '4. Chi tiết Sự kiện'!$B$4:$B$103, "<="&$V$2) -> 0 | V8: =COUNTIFS('4. Chi tiết Sự kiện'!$F$4:$F$103, A8, '4. Chi tiết Sự kiện'!$E$4:$E$103, "Khách mời", '4. Chi tiết Sự kiện'!$B$4:$B$103, ">="&$V$1, '4. Chi tiết Sự kiện'!$B$4:$B$103, "<="&$V$2) -> 0 | W8: =SUMIFS('4. Chi tiết Sự kiện'!$L$4:$L$103, '4. Chi tiết Sự kiện'!$C$4:$C$103, A8, '4. Chi tiết Sự kiện'!$B$4:$B$103, ">="&$V$1, '4. Chi tiết Sự kiện'!$B$4:$B$103, "<="&$V$2) -> 0 | X8: =SUMIFS('4. Chi tiết Sự kiện'!$M$4:$M$103, '4. Chi tiết Sự kiện'!$C$4:$C$103, A8, '4. Chi tiết Sự kiện'!$B$4:$B$103, ">="&$V$1, '4. Chi tiết Sự kiện'!$B$4:$B$103, "<="&$V$2) -> 450000 | Y8: =SUMIFS('5. Nhật ký Hợp đồng'!$K$4:$K$103, '5. Nhật ký Hợp đồng'!$E$4:$E$103, A8, '5. Nhật ký Hợp đồng'!$N$4:$N$103, "Đã duyệt", '5. Nhật ký Hợp đồng'!$B$4:$B$103, ">="&$V$1, '5. Nhật ký Hợp đồng'!$B$4:$B$103, "<="&$V$2) + SUMIFS('5. Nhật ký Hợp đồng'!$L$4:$L$103, '5. Nhật ký Hợp đồng'!$G$4:$G$103, A8, '5. Nhật ký Hợp đồng'!$N$4:$N$103, "Đã duyệt", '5. Nhật ký Hợp đồng'!$B$4:$B$103, ">="&$V$1, '5. Nhật ký Hợp đồng'!$B$4:$B$103, "<="&$V$2) + SUMIFS('5. Nhật ký Hợp đồng'!$M$4:$M$103, '5. Nhật ký Hợp đồng'!$I$4:$I$103, A8, '5. Nhật ký Hợp đồng'!$N$4:$N$103, "Đã duyệt", '5. Nhật ký Hợp đồng'!$B$4:$B$103, ">="&$V$1, '5. Nhật ký Hợp đồng'!$B$4:$B$103, "<="&$V$2) -> 0 | Z8: =SUMIFS('7. Nhật ký Đào tạo'!$L$4:$L$103, '7. Nhật ký Đào tạo'!$B$4:$B$103, A8, '7. Nhật ký Đào tạo'!$K$4:$K$103, "Đã duyệt", '7. Nhật ký Đào tạo'!$M$4:$M$103, ">="&$V$1, '7. Nhật ký Đào tạo'!$M$4:$M$103, "<="&$V$2) -> 1818713.4 | AA8: =X8+Y8+Z8-W8 -> 2268713.5
A9: 0912345676 | B9: Đỗ Hoàng Nam | C9: 0912345676 | D9: 001096003333 | E9: 19034444666 | F9: Techcombank | G9: nam.dh@vov.vn | H9: 0912345673 | I9: Trần Thị Vân | J9: Thành viên | K9: Lửa Xanh | L9: =COUNTIF($K$4:$K$40, K9) -> 8 | M9: =COUNTIFS($K$4:$K$40, K9, $J$4:$J$40, "Thành viên") -> 5 | N9: =COUNTIFS($K$4:$K$40, K9, $J$4:$J$40, "Trưởng phòng") -> 1 | O9: =COUNTIFS($K$4:$K$40, K9, $J$4:$J$40, "Phó Giám đốc") -> 1 | P9: =IF(J9="Giám đốc", IF(AND(L9>=20, O9>=1), "Giám đốc", "Thành viên"), IF(J9="Phó Giám đốc", IF(AND(L9>=10, N9>=1), "Phó Giám đốc", "Thành viên"), IF(J9="Trưởng phòng", IF(L9>=5, "Trưởng phòng", "Thành viên"), "Thành viên"))) -> Thành viên | Q9: 2 | R9: Có | S9: Có | T9: =COUNTIFS('4. Chi tiết Sự kiện'!$C$4:$C$103, A9, '4. Chi tiết Sự kiện'!$E$4:$E$103, "Khách mời", '4. Chi tiết Sự kiện'!$H$4:$H$103, "Có", '4. Chi tiết Sự kiện'!$B$4:$B$103, ">="&$V$1, '4. Chi tiết Sự kiện'!$B$4:$B$103, "<="&$V$2) -> 0 | U9: =COUNTIFS('4. Chi tiết Sự kiện'!$F$4:$F$103, A9, '4. Chi tiết Sự kiện'!$B$4:$B$103, ">="&$V$1, '4. Chi tiết Sự kiện'!$B$4:$B$103, "<="&$V$2) -> 0 | V9: =COUNTIFS('4. Chi tiết Sự kiện'!$F$4:$F$103, A9, '4. Chi tiết Sự kiện'!$E$4:$E$103, "Khách mời", '4. Chi tiết Sự kiện'!$B$4:$B$103, ">="&$V$1, '4. Chi tiết Sự kiện'!$B$4:$B$103, "<="&$V$2) -> 0 | W9: =SUMIFS('4. Chi tiết Sự kiện'!$L$4:$L$103, '4. Chi tiết Sự kiện'!$C$4:$C$103, A9, '4. Chi tiết Sự kiện'!$B$4:$B$103, ">="&$V$1, '4. Chi tiết Sự kiện'!$B$4:$B$103, "<="&$V$2) -> 0 | X9: =SUMIFS('4. Chi tiết Sự kiện'!$M$4:$M$103, '4. Chi tiết Sự kiện'!$C$4:$C$103, A9, '4. Chi tiết Sự kiện'!$B$4:$B$103, ">="&$V$1, '4. Chi tiết Sự kiện'!$B$4:$B$103, "<="&$V$2) -> 0 | Y9: =SUMIFS('5. Nhật ký Hợp đồng'!$K$4:$K$103, '5. Nhật ký Hợp đồng'!$E$4:$E$103, A9, '5. Nhật ký Hợp đồng'!$N$4:$N$103, "Đã duyệt", '5. Nhật ký Hợp đồng'!$B$4:$B$103, ">="&$V$1, '5. Nhật ký Hợp đồng'!$B$4:$B$103, "<="&$V$2) + SUMIFS('5. Nhật ký Hợp đồng'!$L$4:$L$103, '5. Nhật ký Hợp đồng'!$G$4:$G$103, A9, '5. Nhật ký Hợp đồng'!$N$4:$N$103, "Đã duyệt", '5. Nhật ký Hợp đồng'!$B$4:$B$103, ">="&$V$1, '5. Nhật ký Hợp đồng'!$B$4:$B$103, "<="&$V$2) + SUMIFS('5. Nhật ký Hợp đồng'!$M$4:$M$103, '5. Nhật ký Hợp đồng'!$I$4:$I$103, A9, '5. Nhật ký Hợp đồng'!$N$4:$N$103, "Đã duyệt", '5. Nhật ký Hợp đồng'!$B$4:$B$103, ">="&$V$1, '5. Nhật ký Hợp đồng'!$B$4:$B$103, "<="&$V$2) -> 0 | Z9: =SUMIFS('7. Nhật ký Đào tạo'!$L$4:$L$103, '7. Nhật ký Đào tạo'!$B$4:$B$103, A9, '7. Nhật ký Đào tạo'!$K$4:$K$103, "Đã duyệt", '7. Nhật ký Đào tạo'!$M$4:$M$103, ">="&$V$1, '7. Nhật ký Đào tạo'!$M$4:$M$103, "<="&$V$2) -> 0 | AA9: =X9+Y9+Z9-W9 -> 0
A10: 0912345677 | B10: Hoàng Quốc Bảo | C10: 0912345677 | D10: 001096004444 | E10: 19034444777 | F10: Techcombank | G10: bao.hq@vov.vn | H10: 0912345671 | I10: Nguyễn Văn Hoàng | J10: Thành viên | K10: Lửa Xanh | L10: =COUNTIF($K$4:$K$40, K10) -> 8 | M10: =COUNTIFS($K$4:$K$40, K10, $J$4:$J$40, "Thành viên") -> 5 | N10: =COUNTIFS($K$4:$K$40, K10, $J$4:$J$40, "Trưởng phòng") -> 1 | O10: =COUNTIFS($K$4:$K$40, K10, $J$4:$J$40, "Phó Giám đốc") -> 1 | P10: =IF(J10="Giám đốc", IF(AND(L10>=20, O10>=1), "Giám đốc", "Thành viên"), IF(J10="Phó Giám đốc", IF(AND(L10>=10, N10>=1), "Phó Giám đốc", "Thành viên"), IF(J10="Trưởng phòng", IF(L10>=5, "Trưởng phòng", "Thành viên"), "Thành viên"))) -> Thành viên | Q10: 0 | R10: Có | S10: Có | T10: =COUNTIFS('4. Chi tiết Sự kiện'!$C$4:$C$103, A10, '4. Chi tiết Sự kiện'!$E$4:$E$103, "Khách mời", '4. Chi tiết Sự kiện'!$H$4:$H$103, "Có", '4. Chi tiết Sự kiện'!$B$4:$B$103, ">="&$V$1, '4. Chi tiết Sự kiện'!$B$4:$B$103, "<="&$V$2) -> 0 | U10: =COUNTIFS('4. Chi tiết Sự kiện'!$F$4:$F$103, A10, '4. Chi tiết Sự kiện'!$B$4:$B$103, ">="&$V$1, '4. Chi tiết Sự kiện'!$B$4:$B$103, "<="&$V$2) -> 0 | V10: =COUNTIFS('4. Chi tiết Sự kiện'!$F$4:$F$103, A10, '4. Chi tiết Sự kiện'!$E$4:$E$103, "Khách mời", '4. Chi tiết Sự kiện'!$B$4:$B$103, ">="&$V$1, '4. Chi tiết Sự kiện'!$B$4:$B$103, "<="&$V$2) -> 0 | W10: =SUMIFS('4. Chi tiết Sự kiện'!$L$4:$L$103, '4. Chi tiết Sự kiện'!$C$4:$C$103, A10, '4. Chi tiết Sự kiện'!$B$4:$B$103, ">="&$V$1, '4. Chi tiết Sự kiện'!$B$4:$B$103, "<="&$V$2) -> 0 | X10: =SUMIFS('4. Chi tiết Sự kiện'!$M$4:$M$103, '4. Chi tiết Sự kiện'!$C$4:$C$103, A10, '4. Chi tiết Sự kiện'!$B$4:$B$103, ">="&$V$1, '4. Chi tiết Sự kiện'!$B$4:$B$103, "<="&$V$2) -> 0 | Y10: =SUMIFS('5. Nhật ký Hợp đồng'!$K$4:$K$103, '5. Nhật ký Hợp đồng'!$E$4:$E$103, A10, '5. Nhật ký Hợp đồng'!$N$4:$N$103, "Đã duyệt", '5. Nhật ký Hợp đồng'!$B$4:$B$103, ">="&$V$1, '5. Nhật ký Hợp đồng'!$B$4:$B$103, "<="&$V$2) + SUMIFS('5. Nhật ký Hợp đồng'!$L$4:$L$103, '5. Nhật ký Hợp đồng'!$G$4:$G$103, A10, '5. Nhật ký Hợp đồng'!$N$4:$N$103, "Đã duyệt", '5. Nhật ký Hợp đồng'!$B$4:$B$103, ">="&$V$1, '5. Nhật ký Hợp đồng'!$B$4:$B$103, "<="&$V$2) + SUMIFS('5. Nhật ký Hợp đồng'!$M$4:$M$103, '5. Nhật ký Hợp đồng'!$I$4:$I$103, A10, '5. Nhật ký Hợp đồng'!$N$4:$N$103, "Đã duyệt", '5. Nhật ký Hợp đồng'!$B$4:$B$103, ">="&$V$1, '5. Nhật ký Hợp đồng'!$B$4:$B$103, "<="&$V$2) -> 0 | Z10: =SUMIFS('7. Nhật ký Đào tạo'!$L$4:$L$103, '7. Nhật ký Đào tạo'!$B$4:$B$103, A10, '7. Nhật ký Đào tạo'!$K$4:$K$103, "Đã duyệt", '7. Nhật ký Đào tạo'!$M$4:$M$103, ">="&$V$1, '7. Nhật ký Đào tạo'!$M$4:$M$103, "<="&$V$2) -> 0 | AA10: =X10+Y10+Z10-W10 -> 0
A11: 0912345678 | B11: Vũ Minh Tuấn | C11: 0912345678 | D11: 001096005555 | E11: 19034444888 | F11: Techcombank | G11: tuan.vm@vov.vn | H11: 0912345671 | I11: Nguyễn Văn Hoàng | J11: Thành viên | K11: Lửa Xanh | L11: =COUNTIF($K$4:$K$40, K11) -> 8 | M11: =COUNTIFS($K$4:$K$40, K11, $J$4:$J$40, "Thành viên") -> 5 | N11: =COUNTIFS($K$4:$K$40, K11, $J$4:$J$40, "Trưởng phòng") -> 1 | O11: =COUNTIFS($K$4:$K$40, K11, $J$4:$J$40, "Phó Giám đốc") -> 1 | P11: =IF(J11="Giám đốc", IF(AND(L11>=20, O11>=1), "Giám đốc", "Thành viên"), IF(J11="Phó Giám đốc", IF(AND(L11>=10, N11>=1), "Phó Giám đốc", "Thành viên"), IF(J11="Trưởng phòng", IF(L11>=5, "Trưởng phòng", "Thành viên"), "Thành viên"))) -> Thành viên | Q11: 0 | R11: Có | S11: Có | T11: =COUNTIFS('4. Chi tiết Sự kiện'!$C$4:$C$103, A11, '4. Chi tiết Sự kiện'!$E$4:$E$103, "Khách mời", '4. Chi tiết Sự kiện'!$H$4:$H$103, "Có", '4. Chi tiết Sự kiện'!$B$4:$B$103, ">="&$V$1, '4. Chi tiết Sự kiện'!$B$4:$B$103, "<="&$V$2) -> 0 | U11: =COUNTIFS('4. Chi tiết Sự kiện'!$F$4:$F$103, A11, '4. Chi tiết Sự kiện'!$B$4:$B$103, ">="&$V$1, '4. Chi tiết Sự kiện'!$B$4:$B$103, "<="&$V$2) -> 0 | V11: =COUNTIFS('4. Chi tiết Sự kiện'!$F$4:$F$103, A11, '4. Chi tiết Sự kiện'!$E$4:$E$103, "Khách mời", '4. Chi tiết Sự kiện'!$B$4:$B$103, ">="&$V$1, '4. Chi tiết Sự kiện'!$B$4:$B$103, "<="&$V$2) -> 0 | W11: =SUMIFS('4. Chi tiết Sự kiện'!$L$4:$L$103, '4. Chi tiết Sự kiện'!$C$4:$C$103, A11, '4. Chi tiết Sự kiện'!$B$4:$B$103, ">="&$V$1, '4. Chi tiết Sự kiện'!$B$4:$B$103, "<="&$V$2) -> 0 | X11: =SUMIFS('4. Chi tiết Sự kiện'!$M$4:$M$103, '4. Chi tiết Sự kiện'!$C$4:$C$103, A11, '4. Chi tiết Sự kiện'!$B$4:$B$103, ">="&$V$1, '4. Chi tiết Sự kiện'!$B$4:$B$103, "<="&$V$2) -> 0 | Y11: =SUMIFS('5. Nhật ký Hợp đồng'!$K$4:$K$103, '5. Nhật ký Hợp đồng'!$E$4:$E$103, A11, '5. Nhật ký Hợp đồng'!$N$4:$N$103, "Đã duyệt", '5. Nhật ký Hợp đồng'!$B$4:$B$103, ">="&$V$1, '5. Nhật ký Hợp đồng'!$B$4:$B$103, "<="&$V$2) + SUMIFS('5. Nhật ký Hợp đồng'!$L$4:$L$103, '5. Nhật ký Hợp đồng'!$G$4:$G$103, A11, '5. Nhật ký Hợp đồng'!$N$4:$N$103, "Đã duyệt", '5. Nhật ký Hợp đồng'!$B$4:$B$103, ">="&$V$1, '5. Nhật ký Hợp đồng'!$B$4:$B$103, "<="&$V$2) + SUMIFS('5. Nhật ký Hợp đồng'!$M$4:$M$103, '5. Nhật ký Hợp đồng'!$I$4:$I$103, A11, '5. Nhật ký Hợp đồng'!$N$4:$N$103, "Đã duyệt", '5. Nhật ký Hợp đồng'!$B$4:$B$103, ">="&$V$1, '5. Nhật ký Hợp đồng'!$B$4:$B$103, "<="&$V$2) -> 0 | Z11: =SUMIFS('7. Nhật ký Đào tạo'!$L$4:$L$103, '7. Nhật ký Đào tạo'!$B$4:$B$103, A11, '7. Nhật ký Đào tạo'!$K$4:$K$103, "Đã duyệt", '7. Nhật ký Đào tạo'!$M$4:$M$103, ">="&$V$1, '7. Nhật ký Đào tạo'!$M$4:$M$103, "<="&$V$2) -> 0 | AA11: =X11+Y11+Z11-W11 -> 0
A12: 0912345679 | B12: Phạm Văn An | C12: 0912345679 | D12: 001096006666 | E12: 19034444999 | F12: Techcombank | G12: an.pv@vov.vn | H12: Công ty | I12: Công ty | J12: Trưởng phòng | K12: Thép | L12: =COUNTIF($K$4:$K$40, K12) -> 2 | M12: =COUNTIFS($K$4:$K$40, K12, $J$4:$J$40, "Thành viên") -> 1 | N12: =COUNTIFS($K$4:$K$40, K12, $J$4:$J$40, "Trưởng phòng") -> 1 | O12: =COUNTIFS($K$4:$K$40, K12, $J$4:$J$40, "Phó Giám đốc") -> 0 | P12: =IF(J12="Giám đốc", IF(AND(L12>=20, O12>=1), "Giám đốc", "Thành viên"), IF(J12="Phó Giám đốc", IF(AND(L12>=10, N12>=1), "Phó Giám đốc", "Thành viên"), IF(J12="Trưởng phòng", IF(L12>=5, "Trưởng phòng", "Thành viên"), "Thành viên"))) -> Thành viên | Q12: 1 | R12: Có | S12: Không | T12: =COUNTIFS('4. Chi tiết Sự kiện'!$C$4:$C$103, A12, '4. Chi tiết Sự kiện'!$E$4:$E$103, "Khách mời", '4. Chi tiết Sự kiện'!$H$4:$H$103, "Có", '4. Chi tiết Sự kiện'!$B$4:$B$103, ">="&$V$1, '4. Chi tiết Sự kiện'!$B$4:$B$103, "<="&$V$2) -> 0 | U12: =COUNTIFS('4. Chi tiết Sự kiện'!$F$4:$F$103, A12, '4. Chi tiết Sự kiện'!$B$4:$B$103, ">="&$V$1, '4. Chi tiết Sự kiện'!$B$4:$B$103, "<="&$V$2) -> 0 | V12: =COUNTIFS('4. Chi tiết Sự kiện'!$F$4:$F$103, A12, '4. Chi tiết Sự kiện'!$E$4:$E$103, "Khách mời", '4. Chi tiết Sự kiện'!$B$4:$B$103, ">="&$V$1, '4. Chi tiết Sự kiện'!$B$4:$B$103, "<="&$V$2) -> 0 | W12: =SUMIFS('4. Chi tiết Sự kiện'!$L$4:$L$103, '4. Chi tiết Sự kiện'!$C$4:$C$103, A12, '4. Chi tiết Sự kiện'!$B$4:$B$103, ">="&$V$1, '4. Chi tiết Sự kiện'!$B$4:$B$103, "<="&$V$2) -> 0 | X12: =SUMIFS('4. Chi tiết Sự kiện'!$M$4:$M$103, '4. Chi tiết Sự kiện'!$C$4:$C$103, A12, '4. Chi tiết Sự kiện'!$B$4:$B$103, ">="&$V$1, '4. Chi tiết Sự kiện'!$B$4:$B$103, "<="&$V$2) -> 0 | Y12: =SUMIFS('5. Nhật ký Hợp đồng'!$K$4:$K$103, '5. Nhật ký Hợp đồng'!$E$4:$E$103, A12, '5. Nhật ký Hợp đồng'!$N$4:$N$103, "Đã duyệt", '5. Nhật ký Hợp đồng'!$B$4:$B$103, ">="&$V$1, '5. Nhật ký Hợp đồng'!$B$4:$B$103, "<="&$V$2) + SUMIFS('5. Nhật ký Hợp đồng'!$L$4:$L$103, '5. Nhật ký Hợp đồng'!$G$4:$G$103, A12, '5. Nhật ký Hợp đồng'!$N$4:$N$103, "Đã duyệt", '5. Nhật ký Hợp đồng'!$B$4:$B$103, ">="&$V$1, '5. Nhật ký Hợp đồng'!$B$4:$B$103, "<="&$V$2) + SUMIFS('5. Nhật ký Hợp đồng'!$M$4:$M$103, '5. Nhật ký Hợp đồng'!$I$4:$I$103, A12, '5. Nhật ký Hợp đồng'!$N$4:$N$103, "Đã duyệt", '5. Nhật ký Hợp đồng'!$B$4:$B$103, ">="&$V$1, '5. Nhật ký Hợp đồng'!$B$4:$B$103, "<="&$V$2) -> 12000000 | Z12: =SUMIFS('7. Nhật ký Đào tạo'!$L$4:$L$103, '7. Nhật ký Đào tạo'!$B$4:$B$103, A12, '7. Nhật ký Đào tạo'!$K$4:$K$103, "Đã duyệt", '7. Nhật ký Đào tạo'!$M$4:$M$103, ">="&$V$1, '7. Nhật ký Đào tạo'!$M$4:$M$103, "<="&$V$2) -> 0 | AA12: =X12+Y12+Z12-W12 -> 12000000
A13: 0912345680 | B13: Đặng Hoài Nam | C13: 0912345680 | D13: 001096007777 | E13: 19034444000 | F13: Techcombank | G13: nam.dh2@vov.vn | H13: 0912345679 | I13: Phạm Văn An | J13: Thành viên | K13: Thép | L13: =COUNTIF($K$4:$K$40, K13) -> 2 | M13: =COUNTIFS($K$4:$K$40, K13, $J$4:$J$40, "Thành viên") -> 1 | N13: =COUNTIFS($K$4:$K$40, K13, $J$4:$J$40, "Trưởng phòng") -> 1 | O13: =COUNTIFS($K$4:$K$40, K13, $J$4:$J$40, "Phó Giám đốc") -> 0 | P13: =IF(J13="Giám đốc", IF(AND(L13>=20, O13>=1), "Giám đốc", "Thành viên"), IF(J13="Phó Giám đốc", IF(AND(L13>=10, N13>=1), "Phó Giám đốc", "Thành viên"), IF(J13="Trưởng phòng", IF(L13>=5, "Trưởng phòng", "Thành viên"), "Thành viên"))) -> Thành viên | Q13: 0 | R13: Không | S13: Không | T13: =COUNTIFS('4. Chi tiết Sự kiện'!$C$4:$C$103, A13, '4. Chi tiết Sự kiện'!$E$4:$E$103, "Khách mời", '4. Chi tiết Sự kiện'!$H$4:$H$103, "Có", '4. Chi tiết Sự kiện'!$B$4:$B$103, ">="&$V$1, '4. Chi tiết Sự kiện'!$B$4:$B$103, "<="&$V$2) -> 0 | U13: =COUNTIFS('4. Chi tiết Sự kiện'!$F$4:$F$103, A13, '4. Chi tiết Sự kiện'!$B$4:$B$103, ">="&$V$1, '4. Chi tiết Sự kiện'!$B$4:$B$103, "<="&$V$2) -> 0 | V13: =COUNTIFS('4. Chi tiết Sự kiện'!$F$4:$F$103, A13, '4. Chi tiết Sự kiện'!$E$4:$E$103, "Khách mời", '4. Chi tiết Sự kiện'!$B$4:$B$103, ">="&$V$1, '4. Chi tiết Sự kiện'!$B$4:$B$103, "<="&$V$2) -> 0 | W13: =SUMIFS('4. Chi tiết Sự kiện'!$L$4:$L$103, '4. Chi tiết Sự kiện'!$C$4:$C$103, A13, '4. Chi tiết Sự kiện'!$B$4:$B$103, ">="&$V$1, '4. Chi tiết Sự kiện'!$B$4:$B$103, "<="&$V$2) -> 0 | X13: =SUMIFS('4. Chi tiết Sự kiện'!$M$4:$M$103, '4. Chi tiết Sự kiện'!$C$4:$C$103, A13, '4. Chi tiết Sự kiện'!$B$4:$B$103, ">="&$V$1, '4. Chi tiết Sự kiện'!$B$4:$B$103, "<="&$V$2) -> 0 | Y13: =SUMIFS('5. Nhật ký Hợp đồng'!$K$4:$K$103, '5. Nhật ký Hợp đồng'!$E$4:$E$103, A13, '5. Nhật ký Hợp đồng'!$N$4:$N$103, "Đã duyệt", '5. Nhật ký Hợp đồng'!$B$4:$B$103, ">="&$V$1, '5. Nhật ký Hợp đồng'!$B$4:$B$103, "<="&$V$2) + SUMIFS('5. Nhật ký Hợp đồng'!$L$4:$L$103, '5. Nhật ký Hợp đồng'!$G$4:$G$103, A13, '5. Nhật ký Hợp đồng'!$N$4:$N$103, "Đã duyệt", '5. Nhật ký Hợp đồng'!$B$4:$B$103, ">="&$V$1, '5. Nhật ký Hợp đồng'!$B$4:$B$103, "<="&$V$2) + SUMIFS('5. Nhật ký Hợp đồng'!$M$4:$M$103, '5. Nhật ký Hợp đồng'!$I$4:$I$103, A13, '5. Nhật ký Hợp đồng'!$N$4:$N$103, "Đã duyệt", '5. Nhật ký Hợp đồng'!$B$4:$B$103, ">="&$V$1, '5. Nhật ký Hợp đồng'!$B$4:$B$103, "<="&$V$2) -> 0 | Z13: =SUMIFS('7. Nhật ký Đào tạo'!$L$4:$L$103, '7. Nhật ký Đào tạo'!$B$4:$B$103, A13, '7. Nhật ký Đào tạo'!$K$4:$K$103, "Đã duyệt", '7. Nhật ký Đào tạo'!$M$4:$M$103, ">="&$V$1, '7. Nhật ký Đào tạo'!$M$4:$M$103, "<="&$V$2) -> 0 | AA13: =X13+Y13+Z13-W13 -> 0
A14: 0912345681 | B14: Trần Văn Phú | C14: 0912345681 | D14: 001096008888 | E14: 19034444111 | F14: Techcombank | G14: phu.tv@vov.vn | H14: Công ty | I14: Công ty | J14: Giám đốc | K14: Kim Cương | L14: =COUNTIF($K$4:$K$40, K14) -> 22 | M14: =COUNTIFS($K$4:$K$40, K14, $J$4:$J$40, "Thành viên") -> 19 | N14: =COUNTIFS($K$4:$K$40, K14, $J$4:$J$40, "Trưởng phòng") -> 1 | O14: =COUNTIFS($K$4:$K$40, K14, $J$4:$J$40, "Phó Giám đốc") -> 1 | P14: =IF(J14="Giám đốc", IF(AND(L14>=20, O14>=1), "Giám đốc", "Thành viên"), IF(J14="Phó Giám đốc", IF(AND(L14>=10, N14>=1), "Phó Giám đốc", "Thành viên"), IF(J14="Trưởng phòng", IF(L14>=5, "Trưởng phòng", "Thành viên"), "Thành viên"))) -> Giám đốc | Q14: 0 | R14: Có | S14: Có | T14: =COUNTIFS('4. Chi tiết Sự kiện'!$C$4:$C$103, A14, '4. Chi tiết Sự kiện'!$E$4:$E$103, "Khách mời", '4. Chi tiết Sự kiện'!$H$4:$H$103, "Có", '4. Chi tiết Sự kiện'!$B$4:$B$103, ">="&$V$1, '4. Chi tiết Sự kiện'!$B$4:$B$103, "<="&$V$2) -> 0 | U14: =COUNTIFS('4. Chi tiết Sự kiện'!$F$4:$F$103, A14, '4. Chi tiết Sự kiện'!$B$4:$B$103, ">="&$V$1, '4. Chi tiết Sự kiện'!$B$4:$B$103, "<="&$V$2) -> 0 | V14: =COUNTIFS('4. Chi tiết Sự kiện'!$F$4:$F$103, A14, '4. Chi tiết Sự kiện'!$E$4:$E$103, "Khách mời", '4. Chi tiết Sự kiện'!$B$4:$B$103, ">="&$V$1, '4. Chi tiết Sự kiện'!$B$4:$B$103, "<="&$V$2) -> 0 | W14: =SUMIFS('4. Chi tiết Sự kiện'!$L$4:$L$103, '4. Chi tiết Sự kiện'!$C$4:$C$103, A14, '4. Chi tiết Sự kiện'!$B$4:$B$103, ">="&$V$1, '4. Chi tiết Sự kiện'!$B$4:$B$103, "<="&$V$2) -> 0 | X14: =SUMIFS('4. Chi tiết Sự kiện'!$M$4:$M$103, '4. Chi tiết Sự kiện'!$C$4:$C$103, A14, '4. Chi tiết Sự kiện'!$B$4:$B$103, ">="&$V$1, '4. Chi tiết Sự kiện'!$B$4:$B$103, "<="&$V$2) -> 0 | Y14: =SUMIFS('5. Nhật ký Hợp đồng'!$K$4:$K$103, '5. Nhật ký Hợp đồng'!$E$4:$E$103, A14, '5. Nhật ký Hợp đồng'!$N$4:$N$103, "Đã duyệt", '5. Nhật ký Hợp đồng'!$B$4:$B$103, ">="&$V$1, '5. Nhật ký Hợp đồng'!$B$4:$B$103, "<="&$V$2) + SUMIFS('5. Nhật ký Hợp đồng'!$L$4:$L$103, '5. Nhật ký Hợp đồng'!$G$4:$G$103, A14, '5. Nhật ký Hợp đồng'!$N$4:$N$103, "Đã duyệt", '5. Nhật ký Hợp đồng'!$B$4:$B$103, ">="&$V$1, '5. Nhật ký Hợp đồng'!$B$4:$B$103, "<="&$V$2) + SUMIFS('5. Nhật ký Hợp đồng'!$M$4:$M$103, '5. Nhật ký Hợp đồng'!$I$4:$I$103, A14, '5. Nhật ký Hợp đồng'!$N$4:$N$103, "Đã duyệt", '5. Nhật ký Hợp đồng'!$B$4:$B$103, ">="&$V$1, '5. Nhật ký Hợp đồng'!$B$4:$B$103, "<="&$V$2) -> 0 | Z14: =SUMIFS('7. Nhật ký Đào tạo'!$L$4:$L$103, '7. Nhật ký Đào tạo'!$B$4:$B$103, A14, '7. Nhật ký Đào tạo'!$K$4:$K$103, "Đã duyệt", '7. Nhật ký Đào tạo'!$M$4:$M$103, ">="&$V$1, '7. Nhật ký Đào tạo'!$M$4:$M$103, "<="&$V$2) -> 0 | AA14: =X14+Y14+Z14-W14 -> 0
A15: 0912345682 | B15: Nguyễn Thị Bình | C15: 0912345682 | D15: 001096009999 | E15: 19034444222 | F15: Techcombank | G15: binh.nt@vov.vn | H15: 0912345681 | I15: Trần Văn Phú | J15: Phó Giám đốc | K15: Kim Cương | L15: =COUNTIF($K$4:$K$40, K15) -> 22 | M15: =COUNTIFS($K$4:$K$40, K15, $J$4:$J$40, "Thành viên") -> 19 | N15: =COUNTIFS($K$4:$K$40, K15, $J$4:$J$40, "Trưởng phòng") -> 1 | O15: =COUNTIFS($K$4:$K$40, K15, $J$4:$J$40, "Phó Giám đốc") -> 1 | P15: =IF(J15="Giám đốc", IF(AND(L15>=20, O15>=1), "Giám đốc", "Thành viên"), IF(J15="Phó Giám đốc", IF(AND(L15>=10, N15>=1), "Phó Giám đốc", "Thành viên"), IF(J15="Trưởng phòng", IF(L15>=5, "Trưởng phòng", "Thành viên"), "Thành viên"))) -> Phó Giám đốc | Q15: 0 | R15: Có | S15: Có | T15: =COUNTIFS('4. Chi tiết Sự kiện'!$C$4:$C$103, A15, '4. Chi tiết Sự kiện'!$E$4:$E$103, "Khách mời", '4. Chi tiết Sự kiện'!$H$4:$H$103, "Có", '4. Chi tiết Sự kiện'!$B$4:$B$103, ">="&$V$1, '4. Chi tiết Sự kiện'!$B$4:$B$103, "<="&$V$2) -> 0 | U15: =COUNTIFS('4. Chi tiết Sự kiện'!$F$4:$F$103, A15, '4. Chi tiết Sự kiện'!$B$4:$B$103, ">="&$V$1, '4. Chi tiết Sự kiện'!$B$4:$B$103, "<="&$V$2) -> 0 | V15: =COUNTIFS('4. Chi tiết Sự kiện'!$F$4:$F$103, A15, '4. Chi tiết Sự kiện'!$E$4:$E$103, "Khách mời", '4. Chi tiết Sự kiện'!$B$4:$B$103, ">="&$V$1, '4. Chi tiết Sự kiện'!$B$4:$B$103, "<="&$V$2) -> 0 | W15: =SUMIFS('4. Chi tiết Sự kiện'!$L$4:$L$103, '4. Chi tiết Sự kiện'!$C$4:$C$103, A15, '4. Chi tiết Sự kiện'!$B$4:$B$103, ">="&$V$1, '4. Chi tiết Sự kiện'!$B$4:$B$103, "<="&$V$2) -> 0 | X15: =SUMIFS('4. Chi tiết Sự kiện'!$M$4:$M$103, '4. Chi tiết Sự kiện'!$C$4:$C$103, A15, '4. Chi tiết Sự kiện'!$B$4:$B$103, ">="&$V$1, '4. Chi tiết Sự kiện'!$B$4:$B$103, "<="&$V$2) -> 0 | Y15: =SUMIFS('5. Nhật ký Hợp đồng'!$K$4:$K$103, '5. Nhật ký Hợp đồng'!$E$4:$E$103, A15, '5. Nhật ký Hợp đồng'!$N$4:$N$103, "Đã duyệt", '5. Nhật ký Hợp đồng'!$B$4:$B$103, ">="&$V$1, '5. Nhật ký Hợp đồng'!$B$4:$B$103, "<="&$V$2) + SUMIFS('5. Nhật ký Hợp đồng'!$L$4:$L$103, '5. Nhật ký Hợp đồng'!$G$4:$G$103, A15, '5. Nhật ký Hợp đồng'!$N$4:$N$103, "Đã duyệt", '5. Nhật ký Hợp đồng'!$B$4:$B$103, ">="&$V$1, '5. Nhật ký Hợp đồng'!$B$4:$B$103, "<="&$V$2) + SUMIFS('5. Nhật ký Hợp đồng'!$M$4:$M$103, '5. Nhật ký Hợp đồng'!$I$4:$I$103, A15, '5. Nhật ký Hợp đồng'!$N$4:$N$103, "Đã duyệt", '5. Nhật ký Hợp đồng'!$B$4:$B$103, ">="&$V$1, '5. Nhật ký Hợp đồng'!$B$4:$B$103, "<="&$V$2) -> 0 | Z15: =SUMIFS('7. Nhật ký Đào tạo'!$L$4:$L$103, '7. Nhật ký Đào tạo'!$B$4:$B$103, A15, '7. Nhật ký Đào tạo'!$K$4:$K$103, "Đã duyệt", '7. Nhật ký Đào tạo'!$M$4:$M$103, ">="&$V$1, '7. Nhật ký Đào tạo'!$M$4:$M$103, "<="&$V$2) -> 0 | AA15: =X15+Y15+Z15-W15 -> 0
... A40: 0987654325 | B40: Khách mời Trịnh Công Sơn | C40: 0987654325 | D40: 001096000000 | E40: 00710004444 | F40: Vietcombank | G40: son.tc@vov.vn | H40: 0912345671 | I40: Nguyễn Văn Hoàng | J40: Thành viên | K40: Không hoạt động | L40: =COUNTIF($K$4:$K$40, K40) -> 5 | M40: =COUNTIFS($K$4:$K$40, K40, $J$4:$J$40, "Thành viên") -> 5 | N40: =COUNTIFS($K$4:$K$40, K40, $J$4:$J$40, "Trưởng phòng") -> 0 | O40: =COUNTIFS($K$4:$K$40, K40, $J$4:$J$40, "Phó Giám đốc") -> 0 | P40: =IF(J40="Giám đốc", IF(AND(L40>=20, O40>=1), "Giám đốc", "Thành viên"), IF(J40="Phó Giám đốc", IF(AND(L40>=10, N40>=1), "Phó Giám đốc", "Thành viên"), IF(J40="Trưởng phòng", IF(L40>=5, "Trưởng phòng", "Thành viên"), "Thành viên"))) -> Thành viên | Q40: 0 | R40: Có | S40: Có | T40: =COUNTIFS('4. Chi tiết Sự kiện'!$C$4:$C$103, A40, '4. Chi tiết Sự kiện'!$E$4:$E$103, "Khách mời", '4. Chi tiết Sự kiện'!$H$4:$H$103, "Có", '4. Chi tiết Sự kiện'!$B$4:$B$103, ">="&$V$1, '4. Chi tiết Sự kiện'!$B$4:$B$103, "<="&$V$2) -> 1 | U40: =COUNTIFS('4. Chi tiết Sự kiện'!$F$4:$F$103, A40, '4. Chi tiết Sự kiện'!$B$4:$B$103, ">="&$V$1, '4. Chi tiết Sự kiện'!$B$4:$B$103, "<="&$V$2) -> 0 | V40: =COUNTIFS('4. Chi tiết Sự kiện'!$F$4:$F$103, A40, '4. Chi tiết Sự kiện'!$E$4:$E$103, "Khách mời", '4. Chi tiết Sự kiện'!$B$4:$B$103, ">="&$V$1, '4. Chi tiết Sự kiện'!$B$4:$B$103, "<="&$V$2) -> 0 | W40: =SUMIFS('4. Chi tiết Sự kiện'!$L$4:$L$103, '4. Chi tiết Sự kiện'!$C$4:$C$103, A40, '4. Chi tiết Sự kiện'!$B$4:$B$103, ">="&$V$1, '4. Chi tiết Sự kiện'!$B$4:$B$103, "<="&$V$2) -> 0 | X40: =SUMIFS('4. Chi tiết Sự kiện'!$M$4:$M$103, '4. Chi tiết Sự kiện'!$C$4:$C$103, A40, '4. Chi tiết Sự kiện'!$B$4:$B$103, ">="&$V$1, '4. Chi tiết Sự kiện'!$B$4:$B$103, "<="&$V$2) -> 0 | Y40: =SUMIFS('5. Nhật ký Hợp đồng'!$K$4:$K$103, '5. Nhật ký Hợp đồng'!$E$4:$E$103, A40, '5. Nhật ký Hợp đồng'!$N$4:$N$103, "Đã duyệt", '5. Nhật ký Hợp đồng'!$B$4:$B$103, ">="&$V$1, '5. Nhật ký Hợp đồng'!$B$4:$B$103, "<="&$V$2) + SUMIFS('5. Nhật ký Hợp đồng'!$L$4:$L$103, '5. Nhật ký Hợp đồng'!$G$4:$G$103, A40, '5. Nhật ký Hợp đồng'!$N$4:$N$103, "Đã duyệt", '5. Nhật ký Hợp đồng'!$B$4:$B$103, ">="&$V$1, '5. Nhật ký Hợp đồng'!$B$4:$B$103, "<="&$V$2) + SUMIFS('5. Nhật ký Hợp đồng'!$M$4:$M$103, '5. Nhật ký Hợp đồng'!$I$4:$I$103, A40, '5. Nhật ký Hợp đồng'!$N$4:$N$103, "Đã duyệt", '5. Nhật ký Hợp đồng'!$B$4:$B$103, ">="&$V$1, '5. Nhật ký Hợp đồng'!$B$4:$B$103, "<="&$V$2) -> 0 | Z40: =SUMIFS('7. Nhật ký Đào tạo'!$L$4:$L$103, '7. Nhật ký Đào tạo'!$B$4:$B$103, A40, '7. Nhật ký Đào tạo'!$K$4:$K$103, "Đã duyệt", '7. Nhật ký Đào tạo'!$M$4:$M$103, ">="&$V$1, '7. Nhật ký Đào tạo'!$M$4:$M$103, "<="&$V$2) -> 0 | AA40: =X40+Y40+Z40-W40 -> 0
A41: TỔNG CỘNG | L41: =SUM(L4:L40) -> 577 | M41: =SUM(M4:M40) -> 485 | N41: =SUM(N4:N40) -> 32 | O41: =SUM(O4:O40) -> 30 | T41: =SUM(T4:T40) -> 8 | U41: =SUM(U4:U40) -> 9 | V41: =SUM(V4:V40) -> 8 | W41: =SUM(W4:W40) -> 0 | X41: =SUM(X4:X40) -> 3000000 | Y41: =SUM(Y4:Y40) -> 37500000 | Z41: =SUM(Z4:Z40) -> 16000000 | AA41: =SUM(AA4:AA40) -> 56500000

Sheet 3. Nhật ký Sự kiện
A1: NHẬT KÝ QUẢN LÝ SỰ KIỆN & CHI PHÍ
A3: Mã Sự kiện | B3: Ngày tổ chức | C3: Tên Sự kiện / Tiệc trà | D3: Địa điểm | E3: Tổng người tham gia | F3: Số lượng Khách mời tham gia | G3: Số lượng Khách mời tham gia đăng ký ăn trà | H3: Số lượng Khách mời không ăn | I3: Tổng thù lao nhân sự (VND) | J3: Tổng Chi phí Tiệc trà (Cty) | K3: Tổng chi phí Sự kiện (VND) | L3: Trạng thái
A4: ST001 | B4: 46235 | C4: Sự kiện Đại hội ra quân | D4: P. Đại Mỗ | E4: =COUNTIF('4. Chi tiết Sự kiện'!$A$4:$A$103, A4) -> 8 | F4: =COUNTIFS('4. Chi tiết Sự kiện'!$A$4:$A$103, A4, '4. Chi tiết Sự kiện'!$E$4:$E$103, "Khách mời") -> 2 | G4: =COUNTIFS('4. Chi tiết Sự kiện'!$A$4:$A$103, A4, '4. Chi tiết Sự kiện'!$E$4:$E$103, "Khách mời", '4. Chi tiết Sự kiện'!$H$4:$H$103, "Có") -> 2 | H4: =COUNTIFS('4. Chi tiết Sự kiện'!$A$4:$A$103, A4, '4. Chi tiết Sự kiện'!$E$4:$E$103, "Khách mời", '4. Chi tiết Sự kiện'!$H$4:$H$103, "Không") -> 0 | I4: =SUMIFS('4. Chi tiết Sự kiện'!$M$4:$M$103, '4. Chi tiết Sự kiện'!$A$4:$A$103, A4) -> 1100000 | J4: =SUMIFS('4. Chi tiết Sự kiện'!$K$4:$K$103, '4. Chi tiết Sự kiện'!$A$4:$A$103, A4) -> 350000 | K4: =I4+J4 -> 1450000 | L4: Đã hoàn thành
A5: ST002 | B5: 46242 | C5: Sự kiện Vĩnh Phúc kết nối | D5: Vĩnh Phúc | E5: =COUNTIF('4. Chi tiết Sự kiện'!$A$4:$A$103, A5) -> 7 | F5: =COUNTIFS('4. Chi tiết Sự kiện'!$A$4:$A$103, A5, '4. Chi tiết Sự kiện'!$E$4:$E$103, "Khách mời") -> 3 | G5: =COUNTIFS('4. Chi tiết Sự kiện'!$A$4:$A$103, A5, '4. Chi tiết Sự kiện'!$E$4:$E$103, "Khách mời", '4. Chi tiết Sự kiện'!$H$4:$H$103, "Có") -> 3 | H5: =COUNTIFS('4. Chi tiết Sự kiện'!$A$4:$A$103, A5, '4. Chi tiết Sự kiện'!$E$4:$E$103, "Khách mời", '4. Chi tiết Sự kiện'!$H$4:$H$103, "Không") -> 0 | I5: =SUMIFS('4. Chi tiết Sự kiện'!$M$4:$M$103, '4. Chi tiết Sự kiện'!$A$4:$A$103, A5) -> 1100000 | J5: =SUMIFS('4. Chi tiết Sự kiện'!$K$4:$K$103, '4. Chi tiết Sự kiện'!$A$4:$A$103, A5) -> 350000 | K5: =I5+J5 -> 1450000 | L5: Đã hoàn thành
A6: ST003 | B6: 46249 | C6: Hội nghị khách hàng Hà Đông | D6: Hà Đông | E6: =COUNTIF('4. Chi tiết Sự kiện'!$A$4:$A$103, A6) -> 6 | F6: =COUNTIFS('4. Chi tiết Sự kiện'!$A$4:$A$103, A6, '4. Chi tiết Sự kiện'!$E$4:$E$103, "Khách mời") -> 3 | G6: =COUNTIFS('4. Chi tiết Sự kiện'!$A$4:$A$103, A6, '4. Chi tiết Sự kiện'!$E$4:$E$103, "Khách mời", '4. Chi tiết Sự kiện'!$H$4:$H$103, "Có") -> 3 | H6: =COUNTIFS('4. Chi tiết Sự kiện'!$A$4:$A$103, A6, '4. Chi tiết Sự kiện'!$E$4:$E$103, "Khách mời", '4. Chi tiết Sự kiện'!$H$4:$H$103, "Không") -> 0 | I6: =SUMIFS('4. Chi tiết Sự kiện'!$M$4:$M$103, '4. Chi tiết Sự kiện'!$A$4:$A$103, A6) -> 800000 | J6: =SUMIFS('4. Chi tiết Sự kiện'!$K$4:$K$103, '4. Chi tiết Sự kiện'!$A$4:$A$103, A6) -> 300000 | K6: =I6+J6 -> 1100000 | L6: Đã hoàn thành
A7: ST004 | B7: 46254 | C7: Tiệc trà định kỳ | D7: Hà Đông | E7: =COUNTIF('4. Chi tiết Sự kiện'!$A$4:$A$103, A7) -> 0 | F7: =COUNTIFS('4. Chi tiết Sự kiện'!$A$4:$A$103, A7, '4. Chi tiết Sự kiện'!$E$4:$E$103, "Khách mời") -> 0 | G7: =COUNTIFS('4. Chi tiết Sự kiện'!$A$4:$A$103, A7, '4. Chi tiết Sự kiện'!$E$4:$E$103, "Khách mời", '4. Chi tiết Sự kiện'!$H$4:$H$103, "Có") -> 0 | H7: =COUNTIFS('4. Chi tiết Sự kiện'!$A$4:$A$103, A7, '4. Chi tiết Sự kiện'!$E$4:$E$103, "Khách mời", '4. Chi tiết Sự kiện'!$H$4:$H$103, "Không") -> 0 | I7: =SUMIFS('4. Chi tiết Sự kiện'!$M$4:$M$103, '4. Chi tiết Sự kiện'!$A$4:$A$103, A7) -> 0 | J7: =SUMIFS('4. Chi tiết Sự kiện'!$K$4:$K$103, '4. Chi tiết Sự kiện'!$A$4:$A$103, A7) -> 0 | K7: =I7+J7 -> 0 | L7: Chờ duyệt
A8: ST005 | B8: 46256 | C8: Tiệc trà định kỳ | D8: Hà Đông | E8: =COUNTIF('4. Chi tiết Sự kiện'!$A$4:$A$103, A8) -> 0 | F8: =COUNTIFS('4. Chi tiết Sự kiện'!$A$4:$A$103, A8, '4. Chi tiết Sự kiện'!$E$4:$E$103, "Khách mời") -> 0 | G8: =COUNTIFS('4. Chi tiết Sự kiện'!$A$4:$A$103, A8, '4. Chi tiết Sự kiện'!$E$4:$E$103, "Khách mời", '4. Chi tiết Sự kiện'!$H$4:$H$103, "Có") -> 0 | H8: =COUNTIFS('4. Chi tiết Sự kiện'!$A$4:$A$103, A8, '4. Chi tiết Sự kiện'!$E$4:$E$103, "Khách mời", '4. Chi tiết Sự kiện'!$H$4:$H$103, "Không") -> 0 | I8: =SUMIFS('4. Chi tiết Sự kiện'!$M$4:$M$103, '4. Chi tiết Sự kiện'!$A$4:$A$103, A8) -> 0 | J8: =SUMIFS('4. Chi tiết Sự kiện'!$K$4:$K$103, '4. Chi tiết Sự kiện'!$A$4:$A$103, A8) -> 0 | K8: =I8+J8 -> 0 | L8: Chờ duyệt
A9: ST006 | B9: 46259 | C9: Tiệc trà định kỳ | D9: Hà Đông | E9: =COUNTIF('4. Chi tiết Sự kiện'!$A$4:$A$103, A9) -> 0 | F9: =COUNTIFS('4. Chi tiết Sự kiện'!$A$4:$A$103, A9, '4. Chi tiết Sự kiện'!$E$4:$E$103, "Khách mời") -> 0 | G9: =COUNTIFS('4. Chi tiết Sự kiện'!$A$4:$A$103, A9, '4. Chi tiết Sự kiện'!$E$4:$E$103, "Khách mời", '4. Chi tiết Sự kiện'!$H$4:$H$103, "Có") -> 0 | H9: =COUNTIFS('4. Chi tiết Sự kiện'!$A$4:$A$103, A9, '4. Chi tiết Sự kiện'!$E$4:$E$103, "Khách mời", '4. Chi tiết Sự kiện'!$H$4:$H$103, "Không") -> 0 | I9: =SUMIFS('4. Chi tiết Sự kiện'!$M$4:$M$103, '4. Chi tiết Sự kiện'!$A$4:$A$103, A9) -> 0 | J9: =SUMIFS('4. Chi tiết Sự kiện'!$K$4:$K$103, '4. Chi tiết Sự kiện'!$A$4:$A$103, A9) -> 0 | K9: =I9+J9 -> 0 | L9: Chờ duyệt
A10: ST007 | B10: 46262 | C10: Tiệc trà định kỳ | D10: Hà Đông | E10: =COUNTIF('4. Chi tiết Sự kiện'!$A$4:$A$103, A10) -> 0 | F10: =COUNTIFS('4. Chi tiết Sự kiện'!$A$4:$A$103, A10, '4. Chi tiết Sự kiện'!$E$4:$E$103, "Khách mời") -> 0 | G10: =COUNTIFS('4. Chi tiết Sự kiện'!$A$4:$A$103, A10, '4. Chi tiết Sự kiện'!$E$4:$E$103, "Khách mời", '4. Chi tiết Sự kiện'!$H$4:$H$103, "Có") -> 0 | H10: =COUNTIFS('4. Chi tiết Sự kiện'!$A$4:$A$103, A10, '4. Chi tiết Sự kiện'!$E$4:$E$103, "Khách mời", '4. Chi tiết Sự kiện'!$H$4:$H$103, "Không") -> 0 | I10: =SUMIFS('4. Chi tiết Sự kiện'!$M$4:$M$103, '4. Chi tiết Sự kiện'!$A$4:$A$103, A10) -> 0 | J10: =SUMIFS('4. Chi tiết Sự kiện'!$K$4:$K$103, '4. Chi tiết Sự kiện'!$A$4:$A$103, A10) -> 0 | K10: =I10+J10 -> 0 | L10: Chờ duyệt
A11: TỔNG CỘNG | E11: =SUM(E4:E10) -> 21 | F11: =SUM(F4:F10) -> 8 | G11: =SUM(G4:G10) -> 8 | H11: =SUM(H4:H10) -> 0 | I11: =SUM(I4:I10) -> 3000000 | J11: =SUM(J4:J10) -> 1000000 | K11: =SUM(K4:K10) -> 4000000

Sheet 4. Chi tiết Sự kiện
A1: BẢNG THEO DÕI TOÀN BỘ NGƯỜI THAM GIA, PHÂN VAI & CHI PHÍ TIỆC TRÀ
A3: Mã Sự kiện | B3: Ngày tổ chức | C3: Mã TV (SĐT) | D3: Họ Tên | E3: Vai trò tham gia | F3: Người mời (Mã TV) | G3: Họ tên Người mời | H3: Đăng ký ăn tiệc trà? (Có/Không) | I3: Lần làm Khách mời (Lũy kế) | J3: Duyệt Công ty hỗ trợ? (Nếu > 5 lần) | K3: Công ty Hỗ trợ tiệc trà (VND) | L3: Khách tự đóng tiệc trà (VND) | M3: Thù lao Sự kiện (VND)
A4: ST001 | B4: 46235 | C4: 0912345671 | D4: Nguyễn Văn Hoàng | E4: MC | H4: Có | I4: =IF(AND(E4="Khách mời", H4="Có"), COUNTIFS($C$4:C4, C4, $E$4:E4, "Khách mời", $H$4:H4, "Có"), 0) -> 0 | J4: Không | K4: =IF(H4="Có", IF(E4<>"Khách mời", 50000, IF(I4<=5, 50000, IF(J4="Có", 50000, 0))), 0) -> 50000 | L4: =IF(AND(H4="Có", E4="Khách mời", I4>5, J4<>"Có"), 50000, 0) -> 0 | M4: =IF(E4="MC", 200000/COUNTIFS($A$4:$A$103, A4, $E$4:$E$103, "MC"), IF(E4="Phụng sự", 300000/COUNTIFS($A$4:$A$103, A4, $E$4:$E$103, "Phụng sự"), IF(E4="Thuyết trình", 300000/COUNTIFS($A$4:$A$103, A4, $E$4:$E$103, "Thuyết trình"), IF(E4="Chốt sự kiện", 300000/COUNTIFS($A$4:$A$103, A4, $E$4:$E$103, "Chốt sự kiện"), 0)))) -> 100000
A5: ST001 | B5: 46235 | C5: 0912345672 | D5: Lê Minh Anh | E5: MC | H5: Không | I5: =IF(AND(E5="Khách mời", H5="Có"), COUNTIFS($C$4:C5, C5, $E$4:E5, "Khách mời", $H$4:H5, "Có"), 0) -> 0 | J5: Không | K5: =IF(H5="Có", IF(E5<>"Khách mời", 50000, IF(I5<=5, 50000, IF(J5="Có", 50000, 0))), 0) -> 0 | L5: =IF(AND(H5="Có", E5="Khách mời", I5>5, J5<>"Có"), 50000, 0) -> 0 | M5: =IF(E5="MC", 200000/COUNTIFS($A$4:$A$103, A5, $E$4:$E$103, "MC"), IF(E5="Phụng sự", 300000/COUNTIFS($A$4:$A$103, A5, $E$4:$E$103, "Phụng sự"), IF(E5="Thuyết trình", 300000/COUNTIFS($A$4:$A$103, A5, $E$4:$E$103, "Thuyết trình"), IF(E5="Chốt sự kiện", 300000/COUNTIFS($A$4:$A$103, A5, $E$4:$E$103, "Chốt sự kiện"), 0)))) -> 100000
A6: ST001 | B6: 46235 | C6: 0912345673 | D6: Trần Thị Vân | E6: Thuyết trình | H6: Có | I6: =IF(AND(E6="Khách mời", H6="Có"), COUNTIFS($C$4:C6, C6, $E$4:E6, "Khách mời", $H$4:H6, "Có"), 0) -> 0 | J6: Không | K6: =IF(H6="Có", IF(E6<>"Khách mời", 50000, IF(I6<=5, 50000, IF(J6="Có", 50000, 0))), 0) -> 50000 | L6: =IF(AND(H6="Có", E6="Khách mời", I6>5, J6<>"Có"), 50000, 0) -> 0 | M6: =IF(E6="MC", 200000/COUNTIFS($A$4:$A$103, A6, $E$4:$E$103, "MC"), IF(E6="Phụng sự", 300000/COUNTIFS($A$4:$A$103, A6, $E$4:$E$103, "Phụng sự"), IF(E6="Thuyết trình", 300000/COUNTIFS($A$4:$A$103, A6, $E$4:$E$103, "Thuyết trình"), IF(E6="Chốt sự kiện", 300000/COUNTIFS($A$4:$A$103, A6, $E$4:$E$103, "Chốt sự kiện"), 0)))) -> 300000
A7: ST001 | B7: 46235 | C7: 0912345674 | D7: Bùi Minh Đức | E7: Phụng sự | H7: Có | I7: =IF(AND(E7="Khách mời", H7="Có"), COUNTIFS($C$4:C7, C7, $E$4:E7, "Khách mời", $H$4:H7, "Có"), 0) -> 0 | J7: Không | K7: =IF(H7="Có", IF(E7<>"Khách mời", 50000, IF(I7<=5, 50000, IF(J7="Có", 50000, 0))), 0) -> 50000 | L7: =IF(AND(H7="Có", E7="Khách mời", I7>5, J7<>"Có"), 50000, 0) -> 0 | M7: =IF(E7="MC", 200000/COUNTIFS($A$4:$A$103, A7, $E$4:$E$103, "MC"), IF(E7="Phụng sự", 300000/COUNTIFS($A$4:$A$103, A7, $E$4:$E$103, "Phụng sự"), IF(E7="Thuyết trình", 300000/COUNTIFS($A$4:$A$103, A7, $E$4:$E$103, "Thuyết trình"), IF(E7="Chốt sự kiện", 300000/COUNTIFS($A$4:$A$103, A7, $E$4:$E$103, "Chốt sự kiện"), 0)))) -> 150000
A8: ST001 | B8: 46235 | C8: 0912345675 | D8: Ngô Thanh Hải | E8: Phụng sự | H8: Có | I8: =IF(AND(E8="Khách mời", H8="Có"), COUNTIFS($C$4:C8, C8, $E$4:E8, "Khách mời", $H$4:H8, "Có"), 0) -> 0 | J8: Không | K8: =IF(H8="Có", IF(E8<>"Khách mời", 50000, IF(I8<=5, 50000, IF(J8="Có", 50000, 0))), 0) -> 50000 | L8: =IF(AND(H8="Có", E8="Khách mời", I8>5, J8<>"Có"), 50000, 0) -> 0 | M8: =IF(E8="MC", 200000/COUNTIFS($A$4:$A$103, A8, $E$4:$E$103, "MC"), IF(E8="Phụng sự", 300000/COUNTIFS($A$4:$A$103, A8, $E$4:$E$103, "Phụng sự"), IF(E8="Thuyết trình", 300000/COUNTIFS($A$4:$A$103, A8, $E$4:$E$103, "Thuyết trình"), IF(E8="Chốt sự kiện", 300000/COUNTIFS($A$4:$A$103, A8, $E$4:$E$103, "Chốt sự kiện"), 0)))) -> 150000
A9: ST001 | B9: 46235 | C9: 0987654321 | D9: Khách mời Chu Văn Hội | E9: Khách mời | F9: 0912345671 | G9: Nguyễn Văn Hoàng | H9: Có | I9: =IF(AND(E9="Khách mời", H9="Có"), COUNTIFS($C$4:C9, C9, $E$4:E9, "Khách mời", $H$4:H9, "Có"), 0) -> 1 | J9: Không | K9: =IF(H9="Có", IF(E9<>"Khách mời", 50000, IF(I9<=5, 50000, IF(J9="Có", 50000, 0))), 0) -> 50000 | L9: =IF(AND(H9="Có", E9="Khách mời", I9>5, J9<>"Có"), 50000, 0) -> 0 | M9: =IF(E9="MC", 200000/COUNTIFS($A$4:$A$103, A9, $E$4:$E$103, "MC"), IF(E9="Phụng sự", 300000/COUNTIFS($A$4:$A$103, A9, $E$4:$E$103, "Phụng sự"), IF(E9="Thuyết trình", 300000/COUNTIFS($A$4:$A$103, A9, $E$4:$E$103, "Thuyết trình"), IF(E9="Chốt sự kiện", 300000/COUNTIFS($A$4:$A$103, A9, $E$4:$E$103, "Chốt sự kiện"), 0)))) -> 0
A10: ST001 | B10: 46235 | C10: 0987654322 | D10: Khách mời Nguyễn Thị Kim | E10: Khách mời | F10: 0912345672 | G10: Lê Minh Anh | H10: Có | I10: =IF(AND(E10="Khách mời", H10="Có"), COUNTIFS($C$4:C10, C10, $E$4:E10, "Khách mời", $H$4:H10, "Có"), 0) -> 1 | J10: Không | K10: =IF(H10="Có", IF(E10<>"Khách mời", 50000, IF(I10<=5, 50000, IF(J10="Có", 50000, 0))), 0) -> 50000 | L10: =IF(AND(H10="Có", E10="Khách mời", I10>5, J10<>"Có"), 50000, 0) -> 0 | M10: =IF(E10="MC", 200000/COUNTIFS($A$4:$A$103, A10, $E$4:$E$103, "MC"), IF(E10="Phụng sự", 300000/COUNTIFS($A$4:$A$103, A10, $E$4:$E$103, "Phụng sự"), IF(E10="Thuyết trình", 300000/COUNTIFS($A$4:$A$103, A10, $E$4:$E$103, "Thuyết trình"), IF(E10="Chốt sự kiện", 300000/COUNTIFS($A$4:$A$103, A10, $E$4:$E$103, "Chốt sự kiện"), 0)))) -> 0
A11: ST001 | B11: 46235 | C11: 0987654323 | D11: Khách mời Phùng sự Nhóm | E11: Chốt sự kiện | F11: 0912345672 | G11: Lê Minh Anh | H11: Có | I11: =IF(AND(E11="Khách mời", H11="Có"), COUNTIFS($C$4:C11, C11, $E$4:E11, "Khách mời", $H$4:H11, "Có"), 0) -> 0 | J11: Không | K11: =IF(H11="Có", IF(E11<>"Khách mời", 50000, IF(I11<=5, 50000, IF(J11="Có", 50000, 0))), 0) -> 50000 | L11: =IF(AND(H11="Có", E11="Khách mời", I11>5, J11<>"Có"), 50000, 0) -> 0 | M11: =IF(E11="MC", 200000/COUNTIFS($A$4:$A$103, A11, $E$4:$E$103, "MC"), IF(E11="Phụng sự", 300000/COUNTIFS($A$4:$A$103, A11, $E$4:$E$103, "Phụng sự"), IF(E11="Thuyết trình", 300000/COUNTIFS($A$4:$A$103, A11, $E$4:$E$103, "Thuyết trình"), IF(E11="Chốt sự kiện", 300000/COUNTIFS($A$4:$A$103, A11, $E$4:$E$103, "Chốt sự kiện"), 0)))) -> 300000
A12: ST002 | B12: 46242 | C12: 0912345671 | D12: Nguyễn Văn Hoàng | E12: MC | H12: Có | I12: =IF(AND(E12="Khách mời", H12="Có"), COUNTIFS($C$4:C12, C12, $E$4:E12, "Khách mời", $H$4:H12, "Có"), 0) -> 0 | J12: Không | K12: =IF(H12="Có", IF(E12<>"Khách mời", 50000, IF(I12<=5, 50000, IF(J12="Có", 50000, 0))), 0) -> 50000 | L12: =IF(AND(H12="Có", E12="Khách mời", I12>5, J12<>"Có"), 50000, 0) -> 0 | M12: =IF(E12="MC", 200000/COUNTIFS($A$4:$A$103, A12, $E$4:$E$103, "MC"), IF(E12="Phụng sự", 300000/COUNTIFS($A$4:$A$103, A12, $E$4:$E$103, "Phụng sự"), IF(E12="Thuyết trình", 300000/COUNTIFS($A$4:$A$103, A12, $E$4:$E$103, "Thuyết trình"), IF(E12="Chốt sự kiện", 300000/COUNTIFS($A$4:$A$103, A12, $E$4:$E$103, "Chốt sự kiện"), 0)))) -> 200000
A13: ST002 | B13: 46242 | C13: 0912345672 | D13: Lê Minh Anh | E13: Thuyết trình | H13: Có | I13: =IF(AND(E13="Khách mời", H13="Có"), COUNTIFS($C$4:C13, C13, $E$4:E13, "Khách mời", $H$4:H13, "Có"), 0) -> 0 | J13: Không | K13: =IF(H13="Có", IF(E13<>"Khách mời", 50000, IF(I13<=5, 50000, IF(J13="Có", 50000, 0))), 0) -> 50000 | L13: =IF(AND(H13="Có", E13="Khách mời", I13>5, J13<>"Có"), 50000, 0) -> 0 | M13: =IF(E13="MC", 200000/COUNTIFS($A$4:$A$103, A13, $E$4:$E$103, "MC"), IF(E13="Phụng sự", 300000/COUNTIFS($A$4:$A$103, A13, $E$4:$E$103, "Phụng sự"), IF(E13="Thuyết trình", 300000/COUNTIFS($A$4:$A$103, A13, $E$4:$E$103, "Thuyết trình"), IF(E13="Chốt sự kiện", 300000/COUNTIFS($A$4:$A$103, A13, $E$4:$E$103, "Chốt sự kiện"), 0)))) -> 300000
A14: ST002 | B14: 46242 | C14: 0912345673 | D14: Trần Thị Vân | E14: Chốt sự kiện | H14: Có | I14: =IF(AND(E14="Khách mời", H14="Có"), COUNTIFS($C$4:C14, C14, $E$4:E14, "Khách mời", $H$4:H14, "Có"), 0) -> 0 | J14: Không | K14: =IF(H14="Có", IF(E14<>"Khách mời", 50000, IF(I14<=5, 50000, IF(J14="Có", 50000, 0))), 0) -> 50000 | L14: =IF(AND(H14="Có", E14="Khách mời", I14>5, J14<>"Có"), 50000, 0) -> 0 | M14: =IF(E14="MC", 200000/COUNTIFS($A$4:$A$103, A14, $E$4:$E$103, "MC"), IF(E14="Phụng sự", 300000/COUNTIFS($A$4:$A$103, A14, $E$4:$E$103, "Phụng sự"), IF(E14="Thuyết trình", 300000/COUNTIFS($A$4:$A$103, A14, $E$4:$E$103, "Thuyết trình"), IF(E14="Chốt sự kiện", 300000/COUNTIFS($A$4:$A$103, A14, $E$4:$E$103, "Chốt sự kiện"), 0)))) -> 300000
A15: ST002 | B15: 46242 | C15: 0912345674 | D15: Bùi Minh Đức | E15: Phụng sự | H15: Có | I15: =IF(AND(E15="Khách mời", H15="Có"), COUNTIFS($C$4:C15, C15, $E$4:E15, "Khách mời", $H$4:H15, "Có"), 0) -> 0 | J15: Không | K15: =IF(H15="Có", IF(E15<>"Khách mời", 50000, IF(I15<=5, 50000, IF(J15="Có", 50000, 0))), 0) -> 50000 | L15: =IF(AND(H15="Có", E15="Khách mời", I15>5, J15<>"Có"), 50000, 0) -> 0 | M15: =IF(E15="MC", 200000/COUNTIFS($A$4:$A$103, A15, $E$4:$E$103, "MC"), IF(E15="Phụng sự", 300000/COUNTIFS($A$4:$A$103, A15, $E$4:$E$103, "Phụng sự"), IF(E15="Thuyết trình", 300000/COUNTIFS($A$4:$A$103, A15, $E$4:$E$103, "Thuyết trình"), IF(E15="Chốt sự kiện", 300000/COUNTIFS($A$4:$A$103, A15, $E$4:$E$103, "Chốt sự kiện"), 0)))) -> 300000
A16: ST002 | B16: 46242 | C16: 0987654321 | D16: Khách mời Chu Văn Hội | E16: Khách mời | F16: 0912345671 | G16: Nguyễn Văn Hoàng | H16: Có | I16: =IF(AND(E16="Khách mời", H16="Có"), COUNTIFS($C$4:C16, C16, $E$4:E16, "Khách mời", $H$4:H16, "Có"), 0) -> 2 | J16: Không | K16: =IF(H16="Có", IF(E16<>"Khách mời", 50000, IF(I16<=5, 50000, IF(J16="Có", 50000, 0))), 0) -> 50000 | L16: =IF(AND(H16="Có", E16="Khách mời", I16>5, J16<>"Có"), 50000, 0) -> 0 | M16: =IF(E16="MC", 200000/COUNTIFS($A$4:$A$103, A16, $E$4:$E$103, "MC"), IF(E16="Phụng sự", 300000/COUNTIFS($A$4:$A$103, A16, $E$4:$E$103, "Phụng sự"), IF(E16="Thuyết trình", 300000/COUNTIFS($A$4:$A$103, A16, $E$4:$E$103, "Thuyết trình"), IF(E16="Chốt sự kiện", 300000/COUNTIFS($A$4:$A$103, A16, $E$4:$E$103, "Chốt sự kiện"), 0)))) -> 0
A17: ST002 | B17: 46242 | C17: 0987654322 | D17: Khách mời Nguyễn Thị Kim | E17: Khách mời | F17: 0912345672 | G17: Lê Minh Anh | H17: Có | I17: =IF(AND(E17="Khách mời", H17="Có"), COUNTIFS($C$4:C17, C17, $E$4:E17, "Khách mời", $H$4:H17, "Có"), 0) -> 2 | J17: Không | K17: =IF(H17="Có", IF(E17<>"Khách mời", 50000, IF(I17<=5, 50000, IF(J17="Có", 50000, 0))), 0) -> 50000 | L17: =IF(AND(H17="Có", E17="Khách mời", I17>5, J17<>"Có"), 50000, 0) -> 0 | M17: =IF(E17="MC", 200000/COUNTIFS($A$4:$A$103, A17, $E$4:$E$103, "MC"), IF(E17="Phụng sự", 300000/COUNTIFS($A$4:$A$103, A17, $E$4:$E$103, "Phụng sự"), IF(E17="Thuyết trình", 300000/COUNTIFS($A$4:$A$103, A17, $E$4:$E$103, "Thuyết trình"), IF(E17="Chốt sự kiện", 300000/COUNTIFS($A$4:$A$103, A17, $E$4:$E$103, "Chốt sự kiện"), 0)))) -> 0
A18: ST002 | B18: 46242 | C18: 0987654324 | D18: Khách mời Hoàng Văn Nam | E18: Khách mời | F18: 0912345672 | G18: Lê Minh Anh | H18: Có | I18: =IF(AND(E18="Khách mời", H18="Có"), COUNTIFS($C$4:C18, C18, $E$4:E18, "Khách mời", $H$4:H18, "Có"), 0) -> 1 | J18: Không | K18: =IF(H18="Có", IF(E18<>"Khách mời", 50000, IF(I18<=5, 50000, IF(J18="Có", 50000, 0))), 0) -> 50000 | L18: =IF(AND(H18="Có", E18="Khách mời", I18>5, J18<>"Có"), 50000, 0) -> 0 | M18: =IF(E18="MC", 200000/COUNTIFS($A$4:$A$103, A18, $E$4:$E$103, "MC"), IF(E18="Phụng sự", 300000/COUNTIFS($A$4:$A$103, A18, $E$4:$E$103, "Phụng sự"), IF(E18="Thuyết trình", 300000/COUNTIFS($A$4:$A$103, A18, $E$4:$E$103, "Thuyết trình"), IF(E18="Chốt sự kiện", 300000/COUNTIFS($A$4:$A$103, A18, $E$4:$E$103, "Chốt sự kiện"), 0)))) -> 0
A19: ST003 | B19: 46249 | C19: 0912345671 | D19: Nguyễn Văn Hoàng | E19: MC | H19: Có | I19: =IF(AND(E19="Khách mời", H19="Có"), COUNTIFS($C$4:C19, C19, $E$4:E19, "Khách mời", $H$4:H19, "Có"), 0) -> 0 | J19: Không | K19: =IF(H19="Có", IF(E19<>"Khách mời", 50000, IF(I19<=5, 50000, IF(J19="Có", 50000, 0))), 0) -> 50000 | L19: =IF(AND(H19="Có", E19="Khách mời", I19>5, J19<>"Có"), 50000, 0) -> 0 | M19: =IF(E19="MC", 200000/COUNTIFS($A$4:$A$103, A19, $E$4:$E$103, "MC"), IF(E19="Phụng sự", 300000/COUNTIFS($A$4:$A$103, A19, $E$4:$E$103, "Phụng sự"), IF(E19="Thuyết trình", 300000/COUNTIFS($A$4:$A$103, A19, $E$4:$E$103, "Thuyết trình"), IF(E19="Chốt sự kiện", 300000/COUNTIFS($A$4:$A$103, A19, $E$4:$E$103, "Chốt sự kiện"), 0)))) -> 200000
A20: ST003 | B20: 46249 | C20: 0912345675 | D20: Ngô Thanh Hải | E20: Thuyết trình | H20: Có | I20: =IF(AND(E20="Khách mời", H20="Có"), COUNTIFS($C$4:C20, C20, $E$4:E20, "Khách mời", $H$4:H20, "Có"), 0) -> 0 | J20: Không | K20: =IF(H20="Có", IF(E20<>"Khách mời", 50000, IF(I20<=5, 50000, IF(J20="Có", 50000, 0))), 0) -> 50000 | L20: =IF(AND(H20="Có", E20="Khách mời", I20>5, J20<>"Có"), 50000, 0) -> 0 | M20: =IF(E20="MC", 200000/COUNTIFS($A$4:$A$103, A20, $E$4:$E$103, "MC"), IF(E20="Phụng sự", 300000/COUNTIFS($A$4:$A$103, A20, $E$4:$E$103, "Phụng sự"), IF(E20="Thuyết trình", 300000/COUNTIFS($A$4:$A$103, A20, $E$4:$E$103, "Thuyết trình"), IF(E20="Chốt sự kiện", 300000/COUNTIFS($A$4:$A$103, A20, $E$4:$E$103, "Chốt sự kiện"), 0)))) -> 300000
